[2023-06-01T09:06:09.930+0000] {taskinstance.py:1103} INFO - Dependencies all met for dep_context=non-requeueable deps ti=<TaskInstance: my_dag.load manual__2023-06-01T09:05:55.595191+00:00 [queued]>
[2023-06-01T09:06:09.945+0000] {taskinstance.py:1103} INFO - Dependencies all met for dep_context=requeueable deps ti=<TaskInstance: my_dag.load manual__2023-06-01T09:05:55.595191+00:00 [queued]>
[2023-06-01T09:06:09.945+0000] {taskinstance.py:1308} INFO - Starting attempt 1 of 1
[2023-06-01T09:06:09.967+0000] {taskinstance.py:1327} INFO - Executing <Task(DockerOperator): load> on 2023-06-01 09:05:55.595191+00:00
[2023-06-01T09:06:09.975+0000] {standard_task_runner.py:57} INFO - Started process 1430 to run task
[2023-06-01T09:06:09.979+0000] {standard_task_runner.py:84} INFO - Running: ['***', 'tasks', 'run', 'my_dag', 'load', 'manual__2023-06-01T09:05:55.595191+00:00', '--job-id', '39', '--raw', '--subdir', 'DAGS_FOLDER/my_dag.py', '--cfg-path', '/tmp/tmp4t6llr1p']
[2023-06-01T09:06:09.981+0000] {standard_task_runner.py:85} INFO - Job 39: Subtask load
[2023-06-01T09:06:10.032+0000] {task_command.py:410} INFO - Running <TaskInstance: my_dag.load manual__2023-06-01T09:05:55.595191+00:00 [running]> on host 6bccebd655ed
[2023-06-01T09:06:10.147+0000] {taskinstance.py:1547} INFO - Exporting env vars: AIRFLOW_CTX_DAG_OWNER='***' AIRFLOW_CTX_DAG_ID='my_dag' AIRFLOW_CTX_TASK_ID='load' AIRFLOW_CTX_EXECUTION_DATE='2023-06-01T09:05:55.595191+00:00' AIRFLOW_CTX_TRY_NUMBER='1' AIRFLOW_CTX_DAG_RUN_ID='manual__2023-06-01T09:05:55.595191+00:00'
[2023-06-01T09:06:10.185+0000] {docker.py:324} INFO - Starting docker container from image my_etl:load
[2023-06-01T09:06:11.847+0000] {docker.py:391} INFO - Traceback (most recent call last):
  File "/app/load.py", line 15, in <module>
[2023-06-01T09:06:11.848+0000] {docker.py:391} INFO - df = pd.read_sql_table('stating_data',con = engine,schema="public",columns=["First Name","Last name","Age","Sex"])
  File "/usr/local/lib/python3.9/site-packages/pandas/io/sql.py", line 289, in read_sql_table
[2023-06-01T09:06:11.849+0000] {docker.py:391} INFO - table = pandas_sql.read_table(
  File "/usr/local/lib/python3.9/site-packages/pandas/io/sql.py", line 1460, in read_table
[2023-06-01T09:06:11.850+0000] {docker.py:391} INFO - return table.read(
  File "/usr/local/lib/python3.9/site-packages/pandas/io/sql.py", line 995, in read
[2023-06-01T09:06:11.851+0000] {docker.py:391} INFO - cols = [self.table.c[n] for n in columns]
  File "/usr/local/lib/python3.9/site-packages/pandas/io/sql.py", line 995, in <listcomp>
[2023-06-01T09:06:11.852+0000] {docker.py:391} INFO - cols = [self.table.c[n] for n in columns]
  File "/usr/local/lib/python3.9/site-packages/sqlalchemy/sql/base.py", line 1214, in __getitem__
[2023-06-01T09:06:11.853+0000] {docker.py:391} INFO - return self._index[key]
KeyError: 'Last name'
[2023-06-01T09:06:12.339+0000] {taskinstance.py:1824} ERROR - Task failed with exception
Traceback (most recent call last):
  File "/home/airflow/.local/lib/python3.7/site-packages/airflow/providers/docker/operators/docker.py", line 466, in execute
    return self._run_image()
  File "/home/airflow/.local/lib/python3.7/site-packages/airflow/providers/docker/operators/docker.py", line 341, in _run_image
    return self._run_image_with_mounts(self.mounts, add_tmp_variable=False)
  File "/home/airflow/.local/lib/python3.7/site-packages/airflow/providers/docker/operators/docker.py", line 400, in _run_image_with_mounts
    raise AirflowException(f"Docker container failed: {repr(result)} lines {joined_log_lines}")
airflow.exceptions.AirflowException: Docker container failed: {'StatusCode': 1} lines Traceback (most recent call last):
  File "/app/load.py", line 15, in <module>
df = pd.read_sql_table('stating_data',con = engine,schema="public",columns=["First Name","Last name","Age","Sex"])
  File "/usr/local/lib/python3.9/site-packages/pandas/io/sql.py", line 289, in read_sql_table
table = pandas_sql.read_table(
  File "/usr/local/lib/python3.9/site-packages/pandas/io/sql.py", line 1460, in read_table
return table.read(
  File "/usr/local/lib/python3.9/site-packages/pandas/io/sql.py", line 995, in read
cols = [self.table.c[n] for n in columns]
  File "/usr/local/lib/python3.9/site-packages/pandas/io/sql.py", line 995, in <listcomp>
cols = [self.table.c[n] for n in columns]
  File "/usr/local/lib/python3.9/site-packages/sqlalchemy/sql/base.py", line 1214, in __getitem__
return self._index[key]
KeyError: 'Last name'
[2023-06-01T09:06:12.348+0000] {taskinstance.py:1350} INFO - Marking task as FAILED. dag_id=my_dag, task_id=load, execution_date=20230601T090555, start_date=20230601T090609, end_date=20230601T090612
[2023-06-01T09:06:12.377+0000] {standard_task_runner.py:109} ERROR - Failed to execute job 39 for task load (Docker container failed: {'StatusCode': 1} lines Traceback (most recent call last):
  File "/app/load.py", line 15, in <module>
df = pd.read_sql_table('stating_data',con = engine,schema="public",columns=["First Name","Last name","Age","Sex"])
  File "/usr/local/lib/python3.9/site-packages/pandas/io/sql.py", line 289, in read_sql_table
table = pandas_sql.read_table(
  File "/usr/local/lib/python3.9/site-packages/pandas/io/sql.py", line 1460, in read_table
return table.read(
  File "/usr/local/lib/python3.9/site-packages/pandas/io/sql.py", line 995, in read
cols = [self.table.c[n] for n in columns]
  File "/usr/local/lib/python3.9/site-packages/pandas/io/sql.py", line 995, in <listcomp>
cols = [self.table.c[n] for n in columns]
  File "/usr/local/lib/python3.9/site-packages/sqlalchemy/sql/base.py", line 1214, in __getitem__
return self._index[key]
KeyError: 'Last name'; 1430)
[2023-06-01T09:06:12.401+0000] {local_task_job_runner.py:225} INFO - Task exited with return code 1
[2023-06-01T09:06:12.438+0000] {taskinstance.py:2651} INFO - 0 downstream tasks scheduled from follow-on schedule check
