[2023-06-01T08:50:56.774+0000] {taskinstance.py:1103} INFO - Dependencies all met for dep_context=non-requeueable deps ti=<TaskInstance: my_dag.transform manual__2023-06-01T08:47:46.150595+00:00 [queued]>
[2023-06-01T08:50:56.797+0000] {taskinstance.py:1103} INFO - Dependencies all met for dep_context=requeueable deps ti=<TaskInstance: my_dag.transform manual__2023-06-01T08:47:46.150595+00:00 [queued]>
[2023-06-01T08:50:56.798+0000] {taskinstance.py:1308} INFO - Starting attempt 1 of 1
[2023-06-01T08:50:56.826+0000] {taskinstance.py:1327} INFO - Executing <Task(DockerOperator): transform> on 2023-06-01 08:47:46.150595+00:00
[2023-06-01T08:50:56.834+0000] {standard_task_runner.py:57} INFO - Started process 1183 to run task
[2023-06-01T08:50:56.838+0000] {standard_task_runner.py:84} INFO - Running: ['***', 'tasks', 'run', 'my_dag', 'transform', 'manual__2023-06-01T08:47:46.150595+00:00', '--job-id', '32', '--raw', '--subdir', 'DAGS_FOLDER/my_dag.py', '--cfg-path', '/tmp/tmpny0eiz_c']
[2023-06-01T08:50:56.840+0000] {standard_task_runner.py:85} INFO - Job 32: Subtask transform
[2023-06-01T08:50:56.903+0000] {task_command.py:410} INFO - Running <TaskInstance: my_dag.transform manual__2023-06-01T08:47:46.150595+00:00 [running]> on host 6bccebd655ed
[2023-06-01T08:50:57.059+0000] {taskinstance.py:1547} INFO - Exporting env vars: AIRFLOW_CTX_DAG_OWNER='***' AIRFLOW_CTX_DAG_ID='my_dag' AIRFLOW_CTX_TASK_ID='transform' AIRFLOW_CTX_EXECUTION_DATE='2023-06-01T08:47:46.150595+00:00' AIRFLOW_CTX_TRY_NUMBER='1' AIRFLOW_CTX_DAG_RUN_ID='manual__2023-06-01T08:47:46.150595+00:00'
[2023-06-01T08:50:57.128+0000] {docker.py:324} INFO - Starting docker container from image my_etl:transform
[2023-06-01T08:50:59.425+0000] {docker.py:391} INFO - Traceback (most recent call last):
  File "/usr/local/lib/python3.9/site-packages/pandas/core/indexes/base.py", line 3629, in get_loc
[2023-06-01T08:50:59.426+0000] {docker.py:391} INFO - return self._engine.get_loc(casted_key)
  File "pandas/_libs/index.pyx", line 136, in pandas._libs.index.IndexEngine.get_loc
[2023-06-01T08:50:59.427+0000] {docker.py:391} INFO - File "pandas/_libs/index.pyx", line 163, in pandas._libs.index.IndexEngine.get_loc
  File "pandas/_libs/hashtable_class_helper.pxi", line 5198, in pandas._libs.hashtable.PyObjectHashTable.get_item
[2023-06-01T08:50:59.428+0000] {docker.py:391} INFO - File "pandas/_libs/hashtable_class_helper.pxi", line 5206, in pandas._libs.hashtable.PyObjectHashTable.get_item
[2023-06-01T08:50:59.428+0000] {docker.py:391} INFO - KeyError: 'First Name'

The above exception was the direct cause of the following exception:

Traceback (most recent call last):
  File "/app/transform.py", line 11, in <module>
[2023-06-01T08:50:59.429+0000] {docker.py:391} INFO - df['First Name'] = df['First Name'].str.replace(r'[^a-zA-Z0-9 ]', '', regex=True)
  File "/usr/local/lib/python3.9/site-packages/pandas/core/frame.py", line 3505, in __getitem__
[2023-06-01T08:50:59.430+0000] {docker.py:391} INFO - indexer = self.columns.get_loc(key)
  File "/usr/local/lib/python3.9/site-packages/pandas/core/indexes/base.py", line 3631, in get_loc
[2023-06-01T08:50:59.431+0000] {docker.py:391} INFO - raise KeyError(key) from err
KeyError: 'First Name'
[2023-06-01T08:50:59.916+0000] {taskinstance.py:1824} ERROR - Task failed with exception
Traceback (most recent call last):
  File "/home/airflow/.local/lib/python3.7/site-packages/airflow/providers/docker/operators/docker.py", line 466, in execute
    return self._run_image()
  File "/home/airflow/.local/lib/python3.7/site-packages/airflow/providers/docker/operators/docker.py", line 341, in _run_image
    return self._run_image_with_mounts(self.mounts, add_tmp_variable=False)
  File "/home/airflow/.local/lib/python3.7/site-packages/airflow/providers/docker/operators/docker.py", line 400, in _run_image_with_mounts
    raise AirflowException(f"Docker container failed: {repr(result)} lines {joined_log_lines}")
airflow.exceptions.AirflowException: Docker container failed: {'StatusCode': 1} lines Traceback (most recent call last):
  File "/usr/local/lib/python3.9/site-packages/pandas/core/indexes/base.py", line 3629, in get_loc
return self._engine.get_loc(casted_key)
  File "pandas/_libs/index.pyx", line 136, in pandas._libs.index.IndexEngine.get_loc
File "pandas/_libs/index.pyx", line 163, in pandas._libs.index.IndexEngine.get_loc
  File "pandas/_libs/hashtable_class_helper.pxi", line 5198, in pandas._libs.hashtable.PyObjectHashTable.get_item
File "pandas/_libs/hashtable_class_helper.pxi", line 5206, in pandas._libs.hashtable.PyObjectHashTable.get_item
KeyError: 'First Name'

The above exception was the direct cause of the following exception:

Traceback (most recent call last):
  File "/app/transform.py", line 11, in <module>
df['First Name'] = df['First Name'].str.replace(r'[^a-zA-Z0-9 ]', '', regex=True)
  File "/usr/local/lib/python3.9/site-packages/pandas/core/frame.py", line 3505, in __getitem__
indexer = self.columns.get_loc(key)
  File "/usr/local/lib/python3.9/site-packages/pandas/core/indexes/base.py", line 3631, in get_loc
raise KeyError(key) from err
KeyError: 'First Name'
[2023-06-01T08:50:59.926+0000] {taskinstance.py:1350} INFO - Marking task as FAILED. dag_id=my_dag, task_id=transform, execution_date=20230601T084746, start_date=20230601T085056, end_date=20230601T085059
[2023-06-01T08:50:59.955+0000] {standard_task_runner.py:109} ERROR - Failed to execute job 32 for task transform (Docker container failed: {'StatusCode': 1} lines Traceback (most recent call last):
  File "/usr/local/lib/python3.9/site-packages/pandas/core/indexes/base.py", line 3629, in get_loc
return self._engine.get_loc(casted_key)
  File "pandas/_libs/index.pyx", line 136, in pandas._libs.index.IndexEngine.get_loc
File "pandas/_libs/index.pyx", line 163, in pandas._libs.index.IndexEngine.get_loc
  File "pandas/_libs/hashtable_class_helper.pxi", line 5198, in pandas._libs.hashtable.PyObjectHashTable.get_item
File "pandas/_libs/hashtable_class_helper.pxi", line 5206, in pandas._libs.hashtable.PyObjectHashTable.get_item
KeyError: 'First Name'

The above exception was the direct cause of the following exception:

Traceback (most recent call last):
  File "/app/transform.py", line 11, in <module>
df['First Name'] = df['First Name'].str.replace(r'[^a-zA-Z0-9 ]', '', regex=True)
  File "/usr/local/lib/python3.9/site-packages/pandas/core/frame.py", line 3505, in __getitem__
indexer = self.columns.get_loc(key)
  File "/usr/local/lib/python3.9/site-packages/pandas/core/indexes/base.py", line 3631, in get_loc
raise KeyError(key) from err
KeyError: 'First Name'; 1183)
[2023-06-01T08:50:59.978+0000] {local_task_job_runner.py:225} INFO - Task exited with return code 1
[2023-06-01T08:51:00.041+0000] {taskinstance.py:2651} INFO - 0 downstream tasks scheduled from follow-on schedule check
