[2023-05-31T08:50:42.667+0000] {taskinstance.py:1103} INFO - Dependencies all met for dep_context=non-requeueable deps ti=<TaskInstance: my_dag.extract manual__2023-05-31T08:50:36.990760+00:00 [queued]>
[2023-05-31T08:50:42.689+0000] {taskinstance.py:1103} INFO - Dependencies all met for dep_context=requeueable deps ti=<TaskInstance: my_dag.extract manual__2023-05-31T08:50:36.990760+00:00 [queued]>
[2023-05-31T08:50:42.690+0000] {taskinstance.py:1308} INFO - Starting attempt 1 of 1
[2023-05-31T08:50:42.736+0000] {taskinstance.py:1327} INFO - Executing <Task(DockerOperator): extract> on 2023-05-31 08:50:36.990760+00:00
[2023-05-31T08:50:42.746+0000] {standard_task_runner.py:57} INFO - Started process 894 to run task
[2023-05-31T08:50:42.753+0000] {standard_task_runner.py:84} INFO - Running: ['***', 'tasks', 'run', 'my_dag', 'extract', 'manual__2023-05-31T08:50:36.990760+00:00', '--job-id', '48', '--raw', '--subdir', 'DAGS_FOLDER/my_dag.py', '--cfg-path', '/tmp/tmp9mybo3hy']
[2023-05-31T08:50:42.755+0000] {standard_task_runner.py:85} INFO - Job 48: Subtask extract
[2023-05-31T08:50:42.837+0000] {task_command.py:410} INFO - Running <TaskInstance: my_dag.extract manual__2023-05-31T08:50:36.990760+00:00 [running]> on host e578fc747af9
[2023-05-31T08:50:43.116+0000] {taskinstance.py:1547} INFO - Exporting env vars: AIRFLOW_CTX_DAG_OWNER='***' AIRFLOW_CTX_DAG_ID='my_dag' AIRFLOW_CTX_TASK_ID='extract' AIRFLOW_CTX_EXECUTION_DATE='2023-05-31T08:50:36.990760+00:00' AIRFLOW_CTX_TRY_NUMBER='1' AIRFLOW_CTX_DAG_RUN_ID='manual__2023-05-31T08:50:36.990760+00:00'
[2023-05-31T08:50:43.187+0000] {docker.py:324} INFO - Starting docker container from image my_etl:test
[2023-05-31T08:50:46.301+0000] {docker.py:391} INFO - Traceback (most recent call last):
  File "/app/extract.py", line 18, in <module>
    engine = create_engine('postgresql://local:password@postgresLocal:5432/dataPeople', echo=False) #postgresql://username:password@host:port/database
  File "<string>", line 2, in create_engine
[2023-05-31T08:50:46.302+0000] {docker.py:391} INFO - File "/usr/local/lib/python3.9/site-packages/sqlalchemy/util/deprecations.py", line 375, in warned
[2023-05-31T08:50:46.306+0000] {docker.py:391} INFO - return fn(*args, **kwargs)
[2023-05-31T08:50:46.310+0000] {docker.py:391} INFO - File "/usr/local/lib/python3.9/site-packages/sqlalchemy/engine/create.py", line 544, in create_engine
[2023-05-31T08:50:46.314+0000] {docker.py:391} INFO - dbapi = dialect_cls.dbapi(**dbapi_args)
  File "/usr/local/lib/python3.9/site-packages/sqlalchemy/dialects/postgresql/psycopg2.py", line 811, in dbapi
[2023-05-31T08:50:46.315+0000] {docker.py:391} INFO - import psycopg2
ModuleNotFoundError: No module named 'psycopg2'
[2023-05-31T08:50:47.255+0000] {taskinstance.py:1824} ERROR - Task failed with exception
Traceback (most recent call last):
  File "/home/airflow/.local/lib/python3.7/site-packages/airflow/providers/docker/operators/docker.py", line 466, in execute
    return self._run_image()
  File "/home/airflow/.local/lib/python3.7/site-packages/airflow/providers/docker/operators/docker.py", line 341, in _run_image
    return self._run_image_with_mounts(self.mounts, add_tmp_variable=False)
  File "/home/airflow/.local/lib/python3.7/site-packages/airflow/providers/docker/operators/docker.py", line 400, in _run_image_with_mounts
    raise AirflowException(f"Docker container failed: {repr(result)} lines {joined_log_lines}")
airflow.exceptions.AirflowException: Docker container failed: {'StatusCode': 1} lines Traceback (most recent call last):
  File "/app/extract.py", line 18, in <module>
    engine = create_engine('postgresql://local:password@postgresLocal:5432/dataPeople', echo=False) #postgresql://username:password@host:port/database
  File "<string>", line 2, in create_engine
File "/usr/local/lib/python3.9/site-packages/sqlalchemy/util/deprecations.py", line 375, in warned
return fn(*args, **kwargs)
File "/usr/local/lib/python3.9/site-packages/sqlalchemy/engine/create.py", line 544, in create_engine
dbapi = dialect_cls.dbapi(**dbapi_args)
  File "/usr/local/lib/python3.9/site-packages/sqlalchemy/dialects/postgresql/psycopg2.py", line 811, in dbapi
import psycopg2
ModuleNotFoundError: No module named 'psycopg2'
[2023-05-31T08:50:47.269+0000] {taskinstance.py:1350} INFO - Marking task as FAILED. dag_id=my_dag, task_id=extract, execution_date=20230531T085036, start_date=20230531T085042, end_date=20230531T085047
[2023-05-31T08:50:47.312+0000] {standard_task_runner.py:109} ERROR - Failed to execute job 48 for task extract (Docker container failed: {'StatusCode': 1} lines Traceback (most recent call last):
  File "/app/extract.py", line 18, in <module>
    engine = create_engine('postgresql://local:password@postgresLocal:5432/dataPeople', echo=False) #postgresql://username:password@host:port/database
  File "<string>", line 2, in create_engine
File "/usr/local/lib/python3.9/site-packages/sqlalchemy/util/deprecations.py", line 375, in warned
return fn(*args, **kwargs)
File "/usr/local/lib/python3.9/site-packages/sqlalchemy/engine/create.py", line 544, in create_engine
dbapi = dialect_cls.dbapi(**dbapi_args)
  File "/usr/local/lib/python3.9/site-packages/sqlalchemy/dialects/postgresql/psycopg2.py", line 811, in dbapi
import psycopg2
ModuleNotFoundError: No module named 'psycopg2'; 894)
[2023-05-31T08:50:47.346+0000] {local_task_job_runner.py:225} INFO - Task exited with return code 1
[2023-05-31T08:50:47.396+0000] {taskinstance.py:2651} INFO - 0 downstream tasks scheduled from follow-on schedule check
