[2023-05-31T08:45:19.569+0000] {taskinstance.py:1103} INFO - Dependencies all met for dep_context=non-requeueable deps ti=<TaskInstance: my_dag.extract manual__2023-05-31T08:45:17.334626+00:00 [queued]>
[2023-05-31T08:45:19.585+0000] {taskinstance.py:1103} INFO - Dependencies all met for dep_context=requeueable deps ti=<TaskInstance: my_dag.extract manual__2023-05-31T08:45:17.334626+00:00 [queued]>
[2023-05-31T08:45:19.586+0000] {taskinstance.py:1308} INFO - Starting attempt 1 of 1
[2023-05-31T08:45:19.611+0000] {taskinstance.py:1327} INFO - Executing <Task(DockerOperator): extract> on 2023-05-31 08:45:17.334626+00:00
[2023-05-31T08:45:19.619+0000] {standard_task_runner.py:57} INFO - Started process 802 to run task
[2023-05-31T08:45:19.623+0000] {standard_task_runner.py:84} INFO - Running: ['***', 'tasks', 'run', 'my_dag', 'extract', 'manual__2023-05-31T08:45:17.334626+00:00', '--job-id', '47', '--raw', '--subdir', 'DAGS_FOLDER/my_dag.py', '--cfg-path', '/tmp/tmp0x2jopdf']
[2023-05-31T08:45:19.625+0000] {standard_task_runner.py:85} INFO - Job 47: Subtask extract
[2023-05-31T08:45:19.685+0000] {task_command.py:410} INFO - Running <TaskInstance: my_dag.extract manual__2023-05-31T08:45:17.334626+00:00 [running]> on host e578fc747af9
[2023-05-31T08:45:19.815+0000] {taskinstance.py:1547} INFO - Exporting env vars: AIRFLOW_CTX_DAG_OWNER='***' AIRFLOW_CTX_DAG_ID='my_dag' AIRFLOW_CTX_TASK_ID='extract' AIRFLOW_CTX_EXECUTION_DATE='2023-05-31T08:45:17.334626+00:00' AIRFLOW_CTX_TRY_NUMBER='1' AIRFLOW_CTX_DAG_RUN_ID='manual__2023-05-31T08:45:17.334626+00:00'
[2023-05-31T08:45:19.856+0000] {docker.py:324} INFO - Starting docker container from image my_etl:test
[2023-05-31T08:45:21.670+0000] {docker.py:391} INFO - Traceback (most recent call last):
  File "/app/extract.py", line 18, in <module>
    engine = create_engine('postgresql://local:password@postgresLocal:5432/dataPeople', echo=False) #postgresql://username:password@host:port/database
  File "<string>", line 2, in create_engine
[2023-05-31T08:45:21.671+0000] {docker.py:391} INFO - File "/usr/local/lib/python3.9/site-packages/sqlalchemy/util/deprecations.py", line 375, in warned
[2023-05-31T08:45:21.672+0000] {docker.py:391} INFO - return fn(*args, **kwargs)
  File "/usr/local/lib/python3.9/site-packages/sqlalchemy/engine/create.py", line 544, in create_engine
[2023-05-31T08:45:21.673+0000] {docker.py:391} INFO - dbapi = dialect_cls.dbapi(**dbapi_args)
  File "/usr/local/lib/python3.9/site-packages/sqlalchemy/dialects/postgresql/psycopg2.py", line 811, in dbapi
[2023-05-31T08:45:21.674+0000] {docker.py:391} INFO - import psycopg2
ModuleNotFoundError: No module named 'psycopg2'
[2023-05-31T08:45:22.244+0000] {taskinstance.py:1824} ERROR - Task failed with exception
Traceback (most recent call last):
  File "/home/airflow/.local/lib/python3.7/site-packages/airflow/providers/docker/operators/docker.py", line 466, in execute
    return self._run_image()
  File "/home/airflow/.local/lib/python3.7/site-packages/airflow/providers/docker/operators/docker.py", line 341, in _run_image
    return self._run_image_with_mounts(self.mounts, add_tmp_variable=False)
  File "/home/airflow/.local/lib/python3.7/site-packages/airflow/providers/docker/operators/docker.py", line 400, in _run_image_with_mounts
    raise AirflowException(f"Docker container failed: {repr(result)} lines {joined_log_lines}")
airflow.exceptions.AirflowException: Docker container failed: {'StatusCode': 1} lines Traceback (most recent call last):
  File "/app/extract.py", line 18, in <module>
    engine = create_engine('postgresql://local:password@postgresLocal:5432/dataPeople', echo=False) #postgresql://username:password@host:port/database
  File "<string>", line 2, in create_engine
File "/usr/local/lib/python3.9/site-packages/sqlalchemy/util/deprecations.py", line 375, in warned
return fn(*args, **kwargs)
  File "/usr/local/lib/python3.9/site-packages/sqlalchemy/engine/create.py", line 544, in create_engine
dbapi = dialect_cls.dbapi(**dbapi_args)
  File "/usr/local/lib/python3.9/site-packages/sqlalchemy/dialects/postgresql/psycopg2.py", line 811, in dbapi
import psycopg2
ModuleNotFoundError: No module named 'psycopg2'
[2023-05-31T08:45:22.250+0000] {taskinstance.py:1350} INFO - Marking task as FAILED. dag_id=my_dag, task_id=extract, execution_date=20230531T084517, start_date=20230531T084519, end_date=20230531T084522
[2023-05-31T08:45:22.273+0000] {standard_task_runner.py:109} ERROR - Failed to execute job 47 for task extract (Docker container failed: {'StatusCode': 1} lines Traceback (most recent call last):
  File "/app/extract.py", line 18, in <module>
    engine = create_engine('postgresql://local:password@postgresLocal:5432/dataPeople', echo=False) #postgresql://username:password@host:port/database
  File "<string>", line 2, in create_engine
File "/usr/local/lib/python3.9/site-packages/sqlalchemy/util/deprecations.py", line 375, in warned
return fn(*args, **kwargs)
  File "/usr/local/lib/python3.9/site-packages/sqlalchemy/engine/create.py", line 544, in create_engine
dbapi = dialect_cls.dbapi(**dbapi_args)
  File "/usr/local/lib/python3.9/site-packages/sqlalchemy/dialects/postgresql/psycopg2.py", line 811, in dbapi
import psycopg2
ModuleNotFoundError: No module named 'psycopg2'; 802)
[2023-05-31T08:45:22.326+0000] {local_task_job_runner.py:225} INFO - Task exited with return code 1
[2023-05-31T08:45:22.356+0000] {taskinstance.py:2651} INFO - 0 downstream tasks scheduled from follow-on schedule check
