[2023-06-01T09:03:51.920+0000] {taskinstance.py:1103} INFO - Dependencies all met for dep_context=non-requeueable deps ti=<TaskInstance: my_dag.extract manual__2023-06-01T09:03:50.082495+00:00 [queued]>
[2023-06-01T09:03:51.932+0000] {taskinstance.py:1103} INFO - Dependencies all met for dep_context=requeueable deps ti=<TaskInstance: my_dag.extract manual__2023-06-01T09:03:50.082495+00:00 [queued]>
[2023-06-01T09:03:51.932+0000] {taskinstance.py:1308} INFO - Starting attempt 1 of 1
[2023-06-01T09:03:51.953+0000] {taskinstance.py:1327} INFO - Executing <Task(DockerOperator): extract> on 2023-06-01 09:03:50.082495+00:00
[2023-06-01T09:03:51.959+0000] {standard_task_runner.py:57} INFO - Started process 1385 to run task
[2023-06-01T09:03:51.964+0000] {standard_task_runner.py:84} INFO - Running: ['***', 'tasks', 'run', 'my_dag', 'extract', 'manual__2023-06-01T09:03:50.082495+00:00', '--job-id', '36', '--raw', '--subdir', 'DAGS_FOLDER/my_dag.py', '--cfg-path', '/tmp/tmp9fdlq346']
[2023-06-01T09:03:51.966+0000] {standard_task_runner.py:85} INFO - Job 36: Subtask extract
[2023-06-01T09:03:52.018+0000] {task_command.py:410} INFO - Running <TaskInstance: my_dag.extract manual__2023-06-01T09:03:50.082495+00:00 [running]> on host 6bccebd655ed
[2023-06-01T09:03:52.129+0000] {taskinstance.py:1547} INFO - Exporting env vars: AIRFLOW_CTX_DAG_OWNER='***' AIRFLOW_CTX_DAG_ID='my_dag' AIRFLOW_CTX_TASK_ID='extract' AIRFLOW_CTX_EXECUTION_DATE='2023-06-01T09:03:50.082495+00:00' AIRFLOW_CTX_TRY_NUMBER='1' AIRFLOW_CTX_DAG_RUN_ID='manual__2023-06-01T09:03:50.082495+00:00'
[2023-06-01T09:03:52.217+0000] {docker.py:324} INFO - Starting docker container from image my_etl:extract
[2023-06-01T09:03:52.284+0000] {taskinstance.py:1824} ERROR - Task failed with exception
Traceback (most recent call last):
  File "/home/airflow/.local/lib/python3.7/site-packages/docker/api/client.py", line 268, in _raise_for_status
    response.raise_for_status()
  File "/home/airflow/.local/lib/python3.7/site-packages/requests/models.py", line 1021, in raise_for_status
    raise HTTPError(http_error_msg, response=self)
requests.exceptions.HTTPError: 409 Client Error: Conflict for url: http://docker-proxy:2375/v1.42/containers/create?name=extract

The above exception was the direct cause of the following exception:

Traceback (most recent call last):
  File "/home/airflow/.local/lib/python3.7/site-packages/airflow/providers/docker/operators/docker.py", line 466, in execute
    return self._run_image()
  File "/home/airflow/.local/lib/python3.7/site-packages/airflow/providers/docker/operators/docker.py", line 341, in _run_image
    return self._run_image_with_mounts(self.mounts, add_tmp_variable=False)
  File "/home/airflow/.local/lib/python3.7/site-packages/airflow/providers/docker/operators/docker.py", line 381, in _run_image_with_mounts
    hostname=self.hostname,
  File "/home/airflow/.local/lib/python3.7/site-packages/docker/api/container.py", line 431, in create_container
    return self.create_container_from_config(config, name, platform)
  File "/home/airflow/.local/lib/python3.7/site-packages/docker/api/container.py", line 448, in create_container_from_config
    return self._result(res, True)
  File "/home/airflow/.local/lib/python3.7/site-packages/docker/api/client.py", line 274, in _result
    self._raise_for_status(response)
  File "/home/airflow/.local/lib/python3.7/site-packages/docker/api/client.py", line 270, in _raise_for_status
    raise create_api_error_from_http_exception(e) from e
  File "/home/airflow/.local/lib/python3.7/site-packages/docker/errors.py", line 39, in create_api_error_from_http_exception
    raise cls(e, response=response, explanation=explanation) from e
docker.errors.APIError: 409 Client Error for http://docker-proxy:2375/v1.42/containers/create?name=extract: Conflict ("Conflict. The container name "/extract" is already in use by container "bc286b7bb89c3c9de1251d3a90edef53588a25d7831d4041735476a9a533c0bb". You have to remove (or rename) that container to be able to reuse that name.")
[2023-06-01T09:03:52.296+0000] {taskinstance.py:1350} INFO - Marking task as FAILED. dag_id=my_dag, task_id=extract, execution_date=20230601T090350, start_date=20230601T090351, end_date=20230601T090352
[2023-06-01T09:03:52.313+0000] {standard_task_runner.py:109} ERROR - Failed to execute job 36 for task extract (409 Client Error for http://docker-proxy:2375/v1.42/containers/create?name=extract: Conflict ("Conflict. The container name "/extract" is already in use by container "bc286b7bb89c3c9de1251d3a90edef53588a25d7831d4041735476a9a533c0bb". You have to remove (or rename) that container to be able to reuse that name."); 1385)
[2023-06-01T09:03:52.335+0000] {local_task_job_runner.py:225} INFO - Task exited with return code 1
[2023-06-01T09:03:52.372+0000] {taskinstance.py:2651} INFO - 0 downstream tasks scheduled from follow-on schedule check
