[2023-05-23T07:34:36.758+0000] {taskinstance.py:1103} INFO - Dependencies all met for dep_context=non-requeueable deps ti=<TaskInstance: my_dag.Extract manual__2023-05-23T07:32:11.047743+00:00 [queued]>
[2023-05-23T07:34:36.776+0000] {taskinstance.py:1103} INFO - Dependencies all met for dep_context=requeueable deps ti=<TaskInstance: my_dag.Extract manual__2023-05-23T07:32:11.047743+00:00 [queued]>
[2023-05-23T07:34:36.777+0000] {taskinstance.py:1308} INFO - Starting attempt 1 of 1
[2023-05-23T07:34:36.805+0000] {taskinstance.py:1327} INFO - Executing <Task(PythonOperator): Extract> on 2023-05-23 07:32:11.047743+00:00
[2023-05-23T07:34:36.812+0000] {standard_task_runner.py:57} INFO - Started process 58 to run task
[2023-05-23T07:34:36.818+0000] {standard_task_runner.py:84} INFO - Running: ['***', 'tasks', 'run', 'my_dag', 'Extract', 'manual__2023-05-23T07:32:11.047743+00:00', '--job-id', '331', '--raw', '--subdir', 'DAGS_FOLDER/my_dag.py', '--cfg-path', '/tmp/tmpbk_vjnsq']
[2023-05-23T07:34:36.819+0000] {standard_task_runner.py:85} INFO - Job 331: Subtask Extract
[2023-05-23T07:34:36.890+0000] {task_command.py:410} INFO - Running <TaskInstance: my_dag.Extract manual__2023-05-23T07:32:11.047743+00:00 [running]> on host 573a0f9badbc
[2023-05-23T07:34:37.015+0000] {taskinstance.py:1547} INFO - Exporting env vars: AIRFLOW_CTX_DAG_OWNER='***' AIRFLOW_CTX_DAG_ID='my_dag' AIRFLOW_CTX_TASK_ID='Extract' AIRFLOW_CTX_EXECUTION_DATE='2023-05-23T07:32:11.047743+00:00' AIRFLOW_CTX_TRY_NUMBER='1' AIRFLOW_CTX_DAG_RUN_ID='manual__2023-05-23T07:32:11.047743+00:00'
[2023-05-23T07:34:37.019+0000] {taskinstance.py:1824} ERROR - Task failed with exception
Traceback (most recent call last):
  File "/home/airflow/.local/lib/python3.7/site-packages/airflow/operators/python.py", line 181, in execute
    return_value = self.execute_callable()
  File "/home/airflow/.local/lib/python3.7/site-packages/airflow/operators/python.py", line 198, in execute_callable
    return self.python_callable(*self.op_args, **self.op_kwargs)
  File "/opt/airflow/dags/my_dag.py", line 23, in extract
    merged_df = pd.concat(dataFrame)
  File "/home/airflow/.local/lib/python3.7/site-packages/pandas/util/_decorators.py", line 311, in wrapper
    return func(*args, **kwargs)
  File "/home/airflow/.local/lib/python3.7/site-packages/pandas/core/reshape/concat.py", line 304, in concat
    sort=sort,
  File "/home/airflow/.local/lib/python3.7/site-packages/pandas/core/reshape/concat.py", line 351, in __init__
    raise ValueError("No objects to concatenate")
ValueError: No objects to concatenate
[2023-05-23T07:34:37.035+0000] {taskinstance.py:1350} INFO - Marking task as FAILED. dag_id=my_dag, task_id=Extract, execution_date=20230523T073211, start_date=20230523T073436, end_date=20230523T073437
[2023-05-23T07:34:37.053+0000] {standard_task_runner.py:109} ERROR - Failed to execute job 331 for task Extract (No objects to concatenate; 58)
[2023-05-23T07:34:37.069+0000] {local_task_job_runner.py:225} INFO - Task exited with return code 1
[2023-05-23T07:34:37.105+0000] {taskinstance.py:2651} INFO - 0 downstream tasks scheduled from follow-on schedule check
