[2023-05-31T08:41:55.604+0000] {taskinstance.py:1103} INFO - Dependencies all met for dep_context=non-requeueable deps ti=<TaskInstance: my_dag.extract manual__2023-05-31T08:41:53.165253+00:00 [queued]>
[2023-05-31T08:41:55.617+0000] {taskinstance.py:1103} INFO - Dependencies all met for dep_context=requeueable deps ti=<TaskInstance: my_dag.extract manual__2023-05-31T08:41:53.165253+00:00 [queued]>
[2023-05-31T08:41:55.618+0000] {taskinstance.py:1308} INFO - Starting attempt 1 of 1
[2023-05-31T08:41:55.641+0000] {taskinstance.py:1327} INFO - Executing <Task(DockerOperator): extract> on 2023-05-31 08:41:53.165253+00:00
[2023-05-31T08:41:55.649+0000] {standard_task_runner.py:57} INFO - Started process 745 to run task
[2023-05-31T08:41:55.652+0000] {standard_task_runner.py:84} INFO - Running: ['***', 'tasks', 'run', 'my_dag', 'extract', 'manual__2023-05-31T08:41:53.165253+00:00', '--job-id', '46', '--raw', '--subdir', 'DAGS_FOLDER/my_dag.py', '--cfg-path', '/tmp/tmp93puimpl']
[2023-05-31T08:41:55.654+0000] {standard_task_runner.py:85} INFO - Job 46: Subtask extract
[2023-05-31T08:41:55.718+0000] {task_command.py:410} INFO - Running <TaskInstance: my_dag.extract manual__2023-05-31T08:41:53.165253+00:00 [running]> on host e578fc747af9
[2023-05-31T08:41:55.845+0000] {taskinstance.py:1547} INFO - Exporting env vars: AIRFLOW_CTX_DAG_OWNER='***' AIRFLOW_CTX_DAG_ID='my_dag' AIRFLOW_CTX_TASK_ID='extract' AIRFLOW_CTX_EXECUTION_DATE='2023-05-31T08:41:53.165253+00:00' AIRFLOW_CTX_TRY_NUMBER='1' AIRFLOW_CTX_DAG_RUN_ID='manual__2023-05-31T08:41:53.165253+00:00'
[2023-05-31T08:41:55.892+0000] {docker.py:324} INFO - Starting docker container from image my_etl:test
[2023-05-31T08:41:57.534+0000] {docker.py:391} INFO - Traceback (most recent call last):
  File "/app/extract.py", line 16, in <module>
[2023-05-31T08:41:57.535+0000] {docker.py:391} INFO - merged_df = pd.concat(dataFrame)
  File "/usr/local/lib/python3.9/site-packages/pandas/util/_decorators.py", line 311, in wrapper
[2023-05-31T08:41:57.536+0000] {docker.py:391} INFO - return func(*args, **kwargs)
  File "/usr/local/lib/python3.9/site-packages/pandas/core/reshape/concat.py", line 347, in concat
[2023-05-31T08:41:57.537+0000] {docker.py:391} INFO - op = _Concatenator(
  File "/usr/local/lib/python3.9/site-packages/pandas/core/reshape/concat.py", line 404, in __init__
[2023-05-31T08:41:57.538+0000] {docker.py:391} INFO - raise ValueError("No objects to concatenate")
ValueError: No objects to concatenate
[2023-05-31T08:41:57.987+0000] {taskinstance.py:1824} ERROR - Task failed with exception
Traceback (most recent call last):
  File "/home/airflow/.local/lib/python3.7/site-packages/airflow/providers/docker/operators/docker.py", line 466, in execute
    return self._run_image()
  File "/home/airflow/.local/lib/python3.7/site-packages/airflow/providers/docker/operators/docker.py", line 341, in _run_image
    return self._run_image_with_mounts(self.mounts, add_tmp_variable=False)
  File "/home/airflow/.local/lib/python3.7/site-packages/airflow/providers/docker/operators/docker.py", line 400, in _run_image_with_mounts
    raise AirflowException(f"Docker container failed: {repr(result)} lines {joined_log_lines}")
airflow.exceptions.AirflowException: Docker container failed: {'StatusCode': 1} lines Traceback (most recent call last):
  File "/app/extract.py", line 16, in <module>
merged_df = pd.concat(dataFrame)
  File "/usr/local/lib/python3.9/site-packages/pandas/util/_decorators.py", line 311, in wrapper
return func(*args, **kwargs)
  File "/usr/local/lib/python3.9/site-packages/pandas/core/reshape/concat.py", line 347, in concat
op = _Concatenator(
  File "/usr/local/lib/python3.9/site-packages/pandas/core/reshape/concat.py", line 404, in __init__
raise ValueError("No objects to concatenate")
ValueError: No objects to concatenate
[2023-05-31T08:41:57.993+0000] {taskinstance.py:1350} INFO - Marking task as FAILED. dag_id=my_dag, task_id=extract, execution_date=20230531T084153, start_date=20230531T084155, end_date=20230531T084157
[2023-05-31T08:41:58.019+0000] {standard_task_runner.py:109} ERROR - Failed to execute job 46 for task extract (Docker container failed: {'StatusCode': 1} lines Traceback (most recent call last):
  File "/app/extract.py", line 16, in <module>
merged_df = pd.concat(dataFrame)
  File "/usr/local/lib/python3.9/site-packages/pandas/util/_decorators.py", line 311, in wrapper
return func(*args, **kwargs)
  File "/usr/local/lib/python3.9/site-packages/pandas/core/reshape/concat.py", line 347, in concat
op = _Concatenator(
  File "/usr/local/lib/python3.9/site-packages/pandas/core/reshape/concat.py", line 404, in __init__
raise ValueError("No objects to concatenate")
ValueError: No objects to concatenate; 745)
[2023-05-31T08:41:58.043+0000] {local_task_job_runner.py:225} INFO - Task exited with return code 1
[2023-05-31T08:41:58.075+0000] {taskinstance.py:2651} INFO - 0 downstream tasks scheduled from follow-on schedule check
