[2023-06-01T08:01:50.226+0000] {taskinstance.py:1103} INFO - Dependencies all met for dep_context=non-requeueable deps ti=<TaskInstance: my_dag.extract manual__2023-06-01T08:01:47.783110+00:00 [queued]>
[2023-06-01T08:01:50.241+0000] {taskinstance.py:1103} INFO - Dependencies all met for dep_context=requeueable deps ti=<TaskInstance: my_dag.extract manual__2023-06-01T08:01:47.783110+00:00 [queued]>
[2023-06-01T08:01:50.241+0000] {taskinstance.py:1308} INFO - Starting attempt 1 of 1
[2023-06-01T08:01:50.263+0000] {taskinstance.py:1327} INFO - Executing <Task(DockerOperator): extract> on 2023-06-01 08:01:47.783110+00:00
[2023-06-01T08:01:50.270+0000] {standard_task_runner.py:57} INFO - Started process 403 to run task
[2023-06-01T08:01:50.274+0000] {standard_task_runner.py:84} INFO - Running: ['***', 'tasks', 'run', 'my_dag', 'extract', 'manual__2023-06-01T08:01:47.783110+00:00', '--job-id', '16', '--raw', '--subdir', 'DAGS_FOLDER/my_dag.py', '--cfg-path', '/tmp/tmpobgw00sa']
[2023-06-01T08:01:50.277+0000] {standard_task_runner.py:85} INFO - Job 16: Subtask extract
[2023-06-01T08:01:50.333+0000] {task_command.py:410} INFO - Running <TaskInstance: my_dag.extract manual__2023-06-01T08:01:47.783110+00:00 [running]> on host 6bccebd655ed
[2023-06-01T08:01:50.497+0000] {taskinstance.py:1547} INFO - Exporting env vars: AIRFLOW_CTX_DAG_OWNER='***' AIRFLOW_CTX_DAG_ID='my_dag' AIRFLOW_CTX_TASK_ID='extract' AIRFLOW_CTX_EXECUTION_DATE='2023-06-01T08:01:47.783110+00:00' AIRFLOW_CTX_TRY_NUMBER='1' AIRFLOW_CTX_DAG_RUN_ID='manual__2023-06-01T08:01:47.783110+00:00'
[2023-06-01T08:01:50.701+0000] {docker.py:324} INFO - Starting docker container from image my_etl:test11
[2023-06-01T08:01:50.815+0000] {taskinstance.py:1824} ERROR - Task failed with exception
Traceback (most recent call last):
  File "/home/airflow/.local/lib/python3.7/site-packages/docker/api/client.py", line 268, in _raise_for_status
    response.raise_for_status()
  File "/home/airflow/.local/lib/python3.7/site-packages/requests/models.py", line 1021, in raise_for_status
    raise HTTPError(http_error_msg, response=self)
requests.exceptions.HTTPError: 409 Client Error: Conflict for url: http://docker-proxy:2375/v1.42/containers/create?name=etl

The above exception was the direct cause of the following exception:

Traceback (most recent call last):
  File "/home/airflow/.local/lib/python3.7/site-packages/airflow/providers/docker/operators/docker.py", line 466, in execute
    return self._run_image()
  File "/home/airflow/.local/lib/python3.7/site-packages/airflow/providers/docker/operators/docker.py", line 341, in _run_image
    return self._run_image_with_mounts(self.mounts, add_tmp_variable=False)
  File "/home/airflow/.local/lib/python3.7/site-packages/airflow/providers/docker/operators/docker.py", line 381, in _run_image_with_mounts
    hostname=self.hostname,
  File "/home/airflow/.local/lib/python3.7/site-packages/docker/api/container.py", line 431, in create_container
    return self.create_container_from_config(config, name, platform)
  File "/home/airflow/.local/lib/python3.7/site-packages/docker/api/container.py", line 448, in create_container_from_config
    return self._result(res, True)
  File "/home/airflow/.local/lib/python3.7/site-packages/docker/api/client.py", line 274, in _result
    self._raise_for_status(response)
  File "/home/airflow/.local/lib/python3.7/site-packages/docker/api/client.py", line 270, in _raise_for_status
    raise create_api_error_from_http_exception(e) from e
  File "/home/airflow/.local/lib/python3.7/site-packages/docker/errors.py", line 39, in create_api_error_from_http_exception
    raise cls(e, response=response, explanation=explanation) from e
docker.errors.APIError: 409 Client Error for http://docker-proxy:2375/v1.42/containers/create?name=etl: Conflict ("Conflict. The container name "/etl" is already in use by container "d8cb416a176fa115ac10116b3dd0c6c6fd96a805c303a25062d9d3ebfb0a1556". You have to remove (or rename) that container to be able to reuse that name.")
[2023-06-01T08:01:50.833+0000] {taskinstance.py:1350} INFO - Marking task as FAILED. dag_id=my_dag, task_id=extract, execution_date=20230601T080147, start_date=20230601T080150, end_date=20230601T080150
[2023-06-01T08:01:50.875+0000] {standard_task_runner.py:109} ERROR - Failed to execute job 16 for task extract (409 Client Error for http://docker-proxy:2375/v1.42/containers/create?name=etl: Conflict ("Conflict. The container name "/etl" is already in use by container "d8cb416a176fa115ac10116b3dd0c6c6fd96a805c303a25062d9d3ebfb0a1556". You have to remove (or rename) that container to be able to reuse that name."); 403)
[2023-06-01T08:01:50.931+0000] {local_task_job_runner.py:225} INFO - Task exited with return code 1
[2023-06-01T08:01:50.984+0000] {taskinstance.py:2651} INFO - 0 downstream tasks scheduled from follow-on schedule check
