[2023-06-01T08:39:44.768+0000] {taskinstance.py:1103} INFO - Dependencies all met for dep_context=non-requeueable deps ti=<TaskInstance: my_dag.transform manual__2023-06-01T08:39:34.431260+00:00 [queued]>
[2023-06-01T08:39:44.783+0000] {taskinstance.py:1103} INFO - Dependencies all met for dep_context=requeueable deps ti=<TaskInstance: my_dag.transform manual__2023-06-01T08:39:34.431260+00:00 [queued]>
[2023-06-01T08:39:44.784+0000] {taskinstance.py:1308} INFO - Starting attempt 1 of 1
[2023-06-01T08:39:44.808+0000] {taskinstance.py:1327} INFO - Executing <Task(DockerOperator): transform> on 2023-06-01 08:39:34.431260+00:00
[2023-06-01T08:39:44.816+0000] {standard_task_runner.py:57} INFO - Started process 1044 to run task
[2023-06-01T08:39:44.820+0000] {standard_task_runner.py:84} INFO - Running: ['***', 'tasks', 'run', 'my_dag', 'transform', 'manual__2023-06-01T08:39:34.431260+00:00', '--job-id', '28', '--raw', '--subdir', 'DAGS_FOLDER/my_dag.py', '--cfg-path', '/tmp/tmpt2hudo4b']
[2023-06-01T08:39:44.823+0000] {standard_task_runner.py:85} INFO - Job 28: Subtask transform
[2023-06-01T08:39:44.883+0000] {task_command.py:410} INFO - Running <TaskInstance: my_dag.transform manual__2023-06-01T08:39:34.431260+00:00 [running]> on host 6bccebd655ed
[2023-06-01T08:39:45.029+0000] {taskinstance.py:1547} INFO - Exporting env vars: AIRFLOW_CTX_DAG_OWNER='***' AIRFLOW_CTX_DAG_ID='my_dag' AIRFLOW_CTX_TASK_ID='transform' AIRFLOW_CTX_EXECUTION_DATE='2023-06-01T08:39:34.431260+00:00' AIRFLOW_CTX_TRY_NUMBER='1' AIRFLOW_CTX_DAG_RUN_ID='manual__2023-06-01T08:39:34.431260+00:00'
[2023-06-01T08:39:45.078+0000] {docker.py:324} INFO - Starting docker container from image my_etl:transform
[2023-06-01T08:39:46.531+0000] {docker.py:391} INFO - Traceback (most recent call last):
  File "/app/transform.py", line 7, in <module>
    df = pd.read_sql_table('source_data',con = engine,schema="public",columns=["First_Name","Last_name","Age","Sex"])
  File "/usr/local/lib/python3.9/site-packages/pandas/io/sql.py", line 289, in read_sql_table
[2023-06-01T08:39:46.532+0000] {docker.py:391} INFO - table = pandas_sql.read_table(
  File "/usr/local/lib/python3.9/site-packages/pandas/io/sql.py", line 1460, in read_table
[2023-06-01T08:39:46.533+0000] {docker.py:391} INFO - return table.read(
  File "/usr/local/lib/python3.9/site-packages/pandas/io/sql.py", line 995, in read
[2023-06-01T08:39:46.534+0000] {docker.py:391} INFO - cols = [self.table.c[n] for n in columns]
  File "/usr/local/lib/python3.9/site-packages/pandas/io/sql.py", line 995, in <listcomp>
[2023-06-01T08:39:46.535+0000] {docker.py:391} INFO - cols = [self.table.c[n] for n in columns]
  File "/usr/local/lib/python3.9/site-packages/sqlalchemy/sql/base.py", line 1214, in __getitem__
[2023-06-01T08:39:46.535+0000] {docker.py:391} INFO - return self._index[key]
KeyError: 'Last_name'
[2023-06-01T08:39:47.019+0000] {taskinstance.py:1824} ERROR - Task failed with exception
Traceback (most recent call last):
  File "/home/airflow/.local/lib/python3.7/site-packages/airflow/providers/docker/operators/docker.py", line 466, in execute
    return self._run_image()
  File "/home/airflow/.local/lib/python3.7/site-packages/airflow/providers/docker/operators/docker.py", line 341, in _run_image
    return self._run_image_with_mounts(self.mounts, add_tmp_variable=False)
  File "/home/airflow/.local/lib/python3.7/site-packages/airflow/providers/docker/operators/docker.py", line 400, in _run_image_with_mounts
    raise AirflowException(f"Docker container failed: {repr(result)} lines {joined_log_lines}")
airflow.exceptions.AirflowException: Docker container failed: {'StatusCode': 1} lines Traceback (most recent call last):
  File "/app/transform.py", line 7, in <module>
    df = pd.read_sql_table('source_data',con = engine,schema="public",columns=["First_Name","Last_name","Age","Sex"])
  File "/usr/local/lib/python3.9/site-packages/pandas/io/sql.py", line 289, in read_sql_table
table = pandas_sql.read_table(
  File "/usr/local/lib/python3.9/site-packages/pandas/io/sql.py", line 1460, in read_table
return table.read(
  File "/usr/local/lib/python3.9/site-packages/pandas/io/sql.py", line 995, in read
cols = [self.table.c[n] for n in columns]
  File "/usr/local/lib/python3.9/site-packages/pandas/io/sql.py", line 995, in <listcomp>
cols = [self.table.c[n] for n in columns]
  File "/usr/local/lib/python3.9/site-packages/sqlalchemy/sql/base.py", line 1214, in __getitem__
return self._index[key]
KeyError: 'Last_name'
[2023-06-01T08:39:47.025+0000] {taskinstance.py:1350} INFO - Marking task as FAILED. dag_id=my_dag, task_id=transform, execution_date=20230601T083934, start_date=20230601T083944, end_date=20230601T083947
[2023-06-01T08:39:47.045+0000] {standard_task_runner.py:109} ERROR - Failed to execute job 28 for task transform (Docker container failed: {'StatusCode': 1} lines Traceback (most recent call last):
  File "/app/transform.py", line 7, in <module>
    df = pd.read_sql_table('source_data',con = engine,schema="public",columns=["First_Name","Last_name","Age","Sex"])
  File "/usr/local/lib/python3.9/site-packages/pandas/io/sql.py", line 289, in read_sql_table
table = pandas_sql.read_table(
  File "/usr/local/lib/python3.9/site-packages/pandas/io/sql.py", line 1460, in read_table
return table.read(
  File "/usr/local/lib/python3.9/site-packages/pandas/io/sql.py", line 995, in read
cols = [self.table.c[n] for n in columns]
  File "/usr/local/lib/python3.9/site-packages/pandas/io/sql.py", line 995, in <listcomp>
cols = [self.table.c[n] for n in columns]
  File "/usr/local/lib/python3.9/site-packages/sqlalchemy/sql/base.py", line 1214, in __getitem__
return self._index[key]
KeyError: 'Last_name'; 1044)
[2023-06-01T08:39:47.081+0000] {local_task_job_runner.py:225} INFO - Task exited with return code 1
[2023-06-01T08:39:47.120+0000] {taskinstance.py:2651} INFO - 0 downstream tasks scheduled from follow-on schedule check
