[2023-05-25T16:02:35.654+0000] {taskinstance.py:1103} INFO - Dependencies all met for dep_context=non-requeueable deps ti=<TaskInstance: my_dag.python_connectDB manual__2023-05-25T16:02:31.651797+00:00 [queued]>
[2023-05-25T16:02:35.666+0000] {taskinstance.py:1103} INFO - Dependencies all met for dep_context=requeueable deps ti=<TaskInstance: my_dag.python_connectDB manual__2023-05-25T16:02:31.651797+00:00 [queued]>
[2023-05-25T16:02:35.667+0000] {taskinstance.py:1308} INFO - Starting attempt 1 of 1
[2023-05-25T16:02:35.690+0000] {taskinstance.py:1327} INFO - Executing <Task(PythonOperator): python_connectDB> on 2023-05-25 16:02:31.651797+00:00
[2023-05-25T16:02:35.697+0000] {standard_task_runner.py:57} INFO - Started process 85 to run task
[2023-05-25T16:02:35.700+0000] {standard_task_runner.py:84} INFO - Running: ['***', 'tasks', 'run', 'my_dag', 'python_connectDB', 'manual__2023-05-25T16:02:31.651797+00:00', '--job-id', '87', '--raw', '--subdir', 'DAGS_FOLDER/my_dag.py', '--cfg-path', '/tmp/tmpklylnvub']
[2023-05-25T16:02:35.703+0000] {standard_task_runner.py:85} INFO - Job 87: Subtask python_connectDB
[2023-05-25T16:02:35.764+0000] {task_command.py:410} INFO - Running <TaskInstance: my_dag.python_connectDB manual__2023-05-25T16:02:31.651797+00:00 [running]> on host 8f2539ae6c8d
[2023-05-25T16:02:35.884+0000] {taskinstance.py:1547} INFO - Exporting env vars: AIRFLOW_CTX_DAG_OWNER='***' AIRFLOW_CTX_DAG_ID='my_dag' AIRFLOW_CTX_TASK_ID='python_connectDB' AIRFLOW_CTX_EXECUTION_DATE='2023-05-25T16:02:31.651797+00:00' AIRFLOW_CTX_TRY_NUMBER='1' AIRFLOW_CTX_DAG_RUN_ID='manual__2023-05-25T16:02:31.651797+00:00'
[2023-05-25T16:02:45.894+0000] {taskinstance.py:1824} ERROR - Task failed with exception
Traceback (most recent call last):
  File "/home/airflow/.local/lib/python3.7/site-packages/airflow/operators/python.py", line 181, in execute
    return_value = self.execute_callable()
  File "/home/airflow/.local/lib/python3.7/site-packages/airflow/operators/python.py", line 198, in execute_callable
    return self.python_callable(*self.op_args, **self.op_kwargs)
  File "/opt/airflow/dags/my_dag.py", line 81, in connectionDB
    password='password'
  File "/home/airflow/.local/lib/python3.7/site-packages/psycopg2/__init__.py", line 122, in connect
    conn = _connect(dsn, connection_factory=connection_factory, **kwasync)
psycopg2.OperationalError: could not translate host name "postgresLocal" to address: Temporary failure in name resolution

[2023-05-25T16:02:45.910+0000] {taskinstance.py:1350} INFO - Marking task as FAILED. dag_id=my_dag, task_id=python_connectDB, execution_date=20230525T160231, start_date=20230525T160235, end_date=20230525T160245
[2023-05-25T16:02:45.933+0000] {standard_task_runner.py:109} ERROR - Failed to execute job 87 for task python_connectDB (could not translate host name "postgresLocal" to address: Temporary failure in name resolution
; 85)
[2023-05-25T16:02:45.952+0000] {local_task_job_runner.py:225} INFO - Task exited with return code 1
[2023-05-25T16:02:45.983+0000] {taskinstance.py:2651} INFO - 0 downstream tasks scheduled from follow-on schedule check
