[2023-05-31T03:31:30.349+0000] {taskinstance.py:1103} INFO - Dependencies all met for dep_context=non-requeueable deps ti=<TaskInstance: my_dag.Hello manual__2023-05-31T03:31:28.109167+00:00 [queued]>
[2023-05-31T03:31:30.367+0000] {taskinstance.py:1103} INFO - Dependencies all met for dep_context=requeueable deps ti=<TaskInstance: my_dag.Hello manual__2023-05-31T03:31:28.109167+00:00 [queued]>
[2023-05-31T03:31:30.368+0000] {taskinstance.py:1308} INFO - Starting attempt 1 of 1
[2023-05-31T03:31:30.391+0000] {taskinstance.py:1327} INFO - Executing <Task(BashOperator): Hello> on 2023-05-31 03:31:28.109167+00:00
[2023-05-31T03:31:30.398+0000] {standard_task_runner.py:57} INFO - Started process 142 to run task
[2023-05-31T03:31:30.401+0000] {standard_task_runner.py:84} INFO - Running: ['***', 'tasks', 'run', 'my_dag', 'Hello', 'manual__2023-05-31T03:31:28.109167+00:00', '--job-id', '13', '--raw', '--subdir', 'DAGS_FOLDER/my_dag.py', '--cfg-path', '/tmp/tmp3psh4ikp']
[2023-05-31T03:31:30.404+0000] {standard_task_runner.py:85} INFO - Job 13: Subtask Hello
[2023-05-31T03:31:30.469+0000] {task_command.py:410} INFO - Running <TaskInstance: my_dag.Hello manual__2023-05-31T03:31:28.109167+00:00 [running]> on host a3064fb1a2ad
[2023-05-31T03:31:30.596+0000] {taskinstance.py:1547} INFO - Exporting env vars: AIRFLOW_CTX_DAG_OWNER='***' AIRFLOW_CTX_DAG_ID='my_dag' AIRFLOW_CTX_TASK_ID='Hello' AIRFLOW_CTX_EXECUTION_DATE='2023-05-31T03:31:28.109167+00:00' AIRFLOW_CTX_TRY_NUMBER='1' AIRFLOW_CTX_DAG_RUN_ID='manual__2023-05-31T03:31:28.109167+00:00'
[2023-05-31T03:31:30.598+0000] {subprocess.py:63} INFO - Tmp dir root location: 
 /tmp
[2023-05-31T03:31:30.599+0000] {subprocess.py:75} INFO - Running command: ['/bin/bash', '-c', 'python /app/docker/Hello.py']
[2023-05-31T03:31:30.614+0000] {subprocess.py:86} INFO - Output:
[2023-05-31T03:31:30.755+0000] {subprocess.py:93} INFO - python: can't open file '/app/docker/Hello.py': [Errno 2] No such file or directory
[2023-05-31T03:31:30.759+0000] {subprocess.py:97} INFO - Command exited with return code 2
[2023-05-31T03:31:30.775+0000] {taskinstance.py:1824} ERROR - Task failed with exception
Traceback (most recent call last):
  File "/home/airflow/.local/lib/python3.7/site-packages/airflow/operators/bash.py", line 211, in execute
    f"Bash command failed. The command returned a non-zero exit code {result.exit_code}."
airflow.exceptions.AirflowException: Bash command failed. The command returned a non-zero exit code 2.
[2023-05-31T03:31:30.781+0000] {taskinstance.py:1350} INFO - Marking task as FAILED. dag_id=my_dag, task_id=Hello, execution_date=20230531T033128, start_date=20230531T033130, end_date=20230531T033130
[2023-05-31T03:31:30.801+0000] {standard_task_runner.py:109} ERROR - Failed to execute job 13 for task Hello (Bash command failed. The command returned a non-zero exit code 2.; 142)
[2023-05-31T03:31:30.814+0000] {local_task_job_runner.py:225} INFO - Task exited with return code 1
[2023-05-31T03:31:30.838+0000] {taskinstance.py:2651} INFO - 0 downstream tasks scheduled from follow-on schedule check
