[2023-06-01T08:42:09.750+0000] {taskinstance.py:1103} INFO - Dependencies all met for dep_context=non-requeueable deps ti=<TaskInstance: my_dag.transform manual__2023-06-01T08:42:00.495915+00:00 [queued]>
[2023-06-01T08:42:09.774+0000] {taskinstance.py:1103} INFO - Dependencies all met for dep_context=requeueable deps ti=<TaskInstance: my_dag.transform manual__2023-06-01T08:42:00.495915+00:00 [queued]>
[2023-06-01T08:42:09.775+0000] {taskinstance.py:1308} INFO - Starting attempt 1 of 1
[2023-06-01T08:42:11.304+0000] {taskinstance.py:1327} INFO - Executing <Task(DockerOperator): transform> on 2023-06-01 08:42:00.495915+00:00
[2023-06-01T08:42:11.313+0000] {standard_task_runner.py:57} INFO - Started process 1086 to run task
[2023-06-01T08:42:11.316+0000] {standard_task_runner.py:84} INFO - Running: ['***', 'tasks', 'run', 'my_dag', 'transform', 'manual__2023-06-01T08:42:00.495915+00:00', '--job-id', '30', '--raw', '--subdir', 'DAGS_FOLDER/my_dag.py', '--cfg-path', '/tmp/tmpe3y8l2k_']
[2023-06-01T08:42:11.318+0000] {standard_task_runner.py:85} INFO - Job 30: Subtask transform
[2023-06-01T08:42:11.397+0000] {task_command.py:410} INFO - Running <TaskInstance: my_dag.transform manual__2023-06-01T08:42:00.495915+00:00 [running]> on host 6bccebd655ed
[2023-06-01T08:42:12.127+0000] {taskinstance.py:1547} INFO - Exporting env vars: AIRFLOW_CTX_DAG_OWNER='***' AIRFLOW_CTX_DAG_ID='my_dag' AIRFLOW_CTX_TASK_ID='transform' AIRFLOW_CTX_EXECUTION_DATE='2023-06-01T08:42:00.495915+00:00' AIRFLOW_CTX_TRY_NUMBER='1' AIRFLOW_CTX_DAG_RUN_ID='manual__2023-06-01T08:42:00.495915+00:00'
[2023-06-01T08:42:12.219+0000] {docker.py:324} INFO - Starting docker container from image my_etl:transform
[2023-06-01T08:42:14.484+0000] {docker.py:391} INFO - python: can't open file '/app/transform.py': [Errno 2] No such file or directory
[2023-06-01T08:42:15.926+0000] {taskinstance.py:1824} ERROR - Task failed with exception
Traceback (most recent call last):
  File "/home/airflow/.local/lib/python3.7/site-packages/airflow/providers/docker/operators/docker.py", line 466, in execute
    return self._run_image()
  File "/home/airflow/.local/lib/python3.7/site-packages/airflow/providers/docker/operators/docker.py", line 341, in _run_image
    return self._run_image_with_mounts(self.mounts, add_tmp_variable=False)
  File "/home/airflow/.local/lib/python3.7/site-packages/airflow/providers/docker/operators/docker.py", line 400, in _run_image_with_mounts
    raise AirflowException(f"Docker container failed: {repr(result)} lines {joined_log_lines}")
airflow.exceptions.AirflowException: Docker container failed: {'StatusCode': 2} lines python: can't open file '/app/transform.py': [Errno 2] No such file or directory
[2023-06-01T08:42:15.935+0000] {taskinstance.py:1350} INFO - Marking task as FAILED. dag_id=my_dag, task_id=transform, execution_date=20230601T084200, start_date=20230601T084209, end_date=20230601T084215
[2023-06-01T08:42:15.963+0000] {standard_task_runner.py:109} ERROR - Failed to execute job 30 for task transform (Docker container failed: {'StatusCode': 2} lines python: can't open file '/app/transform.py': [Errno 2] No such file or directory; 1086)
[2023-06-01T08:42:16.008+0000] {local_task_job_runner.py:225} INFO - Task exited with return code 1
[2023-06-01T08:42:16.090+0000] {taskinstance.py:2651} INFO - 0 downstream tasks scheduled from follow-on schedule check
