[2023-05-31T08:39:06.272+0000] {taskinstance.py:1103} INFO - Dependencies all met for dep_context=non-requeueable deps ti=<TaskInstance: my_dag.extract manual__2023-05-31T08:39:00.210031+00:00 [queued]>
[2023-05-31T08:39:06.320+0000] {taskinstance.py:1103} INFO - Dependencies all met for dep_context=requeueable deps ti=<TaskInstance: my_dag.extract manual__2023-05-31T08:39:00.210031+00:00 [queued]>
[2023-05-31T08:39:06.321+0000] {taskinstance.py:1308} INFO - Starting attempt 1 of 1
[2023-05-31T08:39:06.392+0000] {taskinstance.py:1327} INFO - Executing <Task(DockerOperator): extract> on 2023-05-31 08:39:00.210031+00:00
[2023-05-31T08:39:06.411+0000] {standard_task_runner.py:57} INFO - Started process 693 to run task
[2023-05-31T08:39:06.417+0000] {standard_task_runner.py:84} INFO - Running: ['***', 'tasks', 'run', 'my_dag', 'extract', 'manual__2023-05-31T08:39:00.210031+00:00', '--job-id', '44', '--raw', '--subdir', 'DAGS_FOLDER/my_dag.py', '--cfg-path', '/tmp/tmp75ee8ua0']
[2023-05-31T08:39:06.423+0000] {standard_task_runner.py:85} INFO - Job 44: Subtask extract
[2023-05-31T08:39:06.712+0000] {task_command.py:410} INFO - Running <TaskInstance: my_dag.extract manual__2023-05-31T08:39:00.210031+00:00 [running]> on host e578fc747af9
[2023-05-31T08:39:07.403+0000] {taskinstance.py:1547} INFO - Exporting env vars: AIRFLOW_CTX_DAG_OWNER='***' AIRFLOW_CTX_DAG_ID='my_dag' AIRFLOW_CTX_TASK_ID='extract' AIRFLOW_CTX_EXECUTION_DATE='2023-05-31T08:39:00.210031+00:00' AIRFLOW_CTX_TRY_NUMBER='1' AIRFLOW_CTX_DAG_RUN_ID='manual__2023-05-31T08:39:00.210031+00:00'
[2023-05-31T08:39:07.636+0000] {docker.py:324} INFO - Starting docker container from image my_etl:test
[2023-05-31T08:39:14.033+0000] {docker.py:391} INFO - python: can't open file '/extract.py': [Errno 2] No such file or directory
[2023-05-31T08:39:14.693+0000] {taskinstance.py:1824} ERROR - Task failed with exception
Traceback (most recent call last):
  File "/home/airflow/.local/lib/python3.7/site-packages/airflow/providers/docker/operators/docker.py", line 466, in execute
    return self._run_image()
  File "/home/airflow/.local/lib/python3.7/site-packages/airflow/providers/docker/operators/docker.py", line 341, in _run_image
    return self._run_image_with_mounts(self.mounts, add_tmp_variable=False)
  File "/home/airflow/.local/lib/python3.7/site-packages/airflow/providers/docker/operators/docker.py", line 400, in _run_image_with_mounts
    raise AirflowException(f"Docker container failed: {repr(result)} lines {joined_log_lines}")
airflow.exceptions.AirflowException: Docker container failed: {'StatusCode': 2} lines python: can't open file '/extract.py': [Errno 2] No such file or directory
[2023-05-31T08:39:14.704+0000] {taskinstance.py:1350} INFO - Marking task as FAILED. dag_id=my_dag, task_id=extract, execution_date=20230531T083900, start_date=20230531T083906, end_date=20230531T083914
[2023-05-31T08:39:14.756+0000] {standard_task_runner.py:109} ERROR - Failed to execute job 44 for task extract (Docker container failed: {'StatusCode': 2} lines python: can't open file '/extract.py': [Errno 2] No such file or directory; 693)
[2023-05-31T08:39:14.819+0000] {local_task_job_runner.py:225} INFO - Task exited with return code 1
[2023-05-31T08:39:14.900+0000] {taskinstance.py:2651} INFO - 0 downstream tasks scheduled from follow-on schedule check
