[2023-05-27T14:02:36.166+0000] {taskinstance.py:1103} INFO - Dependencies all met for dep_context=non-requeueable deps ti=<TaskInstance: my_dag.Load manual__2023-05-27T13:56:46.016071+00:00 [queued]>
[2023-05-27T14:02:36.186+0000] {taskinstance.py:1103} INFO - Dependencies all met for dep_context=requeueable deps ti=<TaskInstance: my_dag.Load manual__2023-05-27T13:56:46.016071+00:00 [queued]>
[2023-05-27T14:02:36.187+0000] {taskinstance.py:1308} INFO - Starting attempt 1 of 1
[2023-05-27T14:02:36.215+0000] {taskinstance.py:1327} INFO - Executing <Task(BashOperator): Load> on 2023-05-27 13:56:46.016071+00:00
[2023-05-27T14:02:36.224+0000] {standard_task_runner.py:57} INFO - Started process 164 to run task
[2023-05-27T14:02:36.228+0000] {standard_task_runner.py:84} INFO - Running: ['***', 'tasks', 'run', 'my_dag', 'Load', 'manual__2023-05-27T13:56:46.016071+00:00', '--job-id', '150', '--raw', '--subdir', 'DAGS_FOLDER/my_dag.py', '--cfg-path', '/tmp/tmps7vja01x']
[2023-05-27T14:02:36.231+0000] {standard_task_runner.py:85} INFO - Job 150: Subtask Load
[2023-05-27T14:02:36.307+0000] {task_command.py:410} INFO - Running <TaskInstance: my_dag.Load manual__2023-05-27T13:56:46.016071+00:00 [running]> on host d1b315133606
[2023-05-27T14:02:36.460+0000] {taskinstance.py:1547} INFO - Exporting env vars: AIRFLOW_CTX_DAG_OWNER='***' AIRFLOW_CTX_DAG_ID='my_dag' AIRFLOW_CTX_TASK_ID='Load' AIRFLOW_CTX_EXECUTION_DATE='2023-05-27T13:56:46.016071+00:00' AIRFLOW_CTX_TRY_NUMBER='1' AIRFLOW_CTX_DAG_RUN_ID='manual__2023-05-27T13:56:46.016071+00:00'
[2023-05-27T14:02:36.465+0000] {subprocess.py:63} INFO - Tmp dir root location: 
 /tmp
[2023-05-27T14:02:36.466+0000] {subprocess.py:75} INFO - Running command: ['/bin/bash', '-c', 'python /opt/***/dags/load.py']
[2023-05-27T14:02:36.482+0000] {subprocess.py:86} INFO - Output:
[2023-05-27T14:02:39.307+0000] {subprocess.py:93} INFO - Traceback (most recent call last):
[2023-05-27T14:02:39.308+0000] {subprocess.py:93} INFO -   File "/home/***/.local/lib/python3.7/site-packages/sqlalchemy/engine/base.py", line 3366, in _wrap_pool_connect
[2023-05-27T14:02:39.309+0000] {subprocess.py:93} INFO -     return fn()
[2023-05-27T14:02:39.311+0000] {subprocess.py:93} INFO -   File "/home/***/.local/lib/python3.7/site-packages/sqlalchemy/pool/base.py", line 327, in connect
[2023-05-27T14:02:39.312+0000] {subprocess.py:93} INFO -     return _ConnectionFairy._checkout(self)
[2023-05-27T14:02:39.313+0000] {subprocess.py:93} INFO -   File "/home/***/.local/lib/python3.7/site-packages/sqlalchemy/pool/base.py", line 894, in _checkout
[2023-05-27T14:02:39.314+0000] {subprocess.py:93} INFO -     fairy = _ConnectionRecord.checkout(pool)
[2023-05-27T14:02:39.315+0000] {subprocess.py:93} INFO -   File "/home/***/.local/lib/python3.7/site-packages/sqlalchemy/pool/base.py", line 493, in checkout
[2023-05-27T14:02:39.316+0000] {subprocess.py:93} INFO -     rec = pool._do_get()
[2023-05-27T14:02:39.317+0000] {subprocess.py:93} INFO -   File "/home/***/.local/lib/python3.7/site-packages/sqlalchemy/pool/impl.py", line 146, in _do_get
[2023-05-27T14:02:39.318+0000] {subprocess.py:93} INFO -     self._dec_overflow()
[2023-05-27T14:02:39.319+0000] {subprocess.py:93} INFO -   File "/home/***/.local/lib/python3.7/site-packages/sqlalchemy/util/langhelpers.py", line 72, in __exit__
[2023-05-27T14:02:39.320+0000] {subprocess.py:93} INFO -     with_traceback=exc_tb,
[2023-05-27T14:02:39.321+0000] {subprocess.py:93} INFO -   File "/home/***/.local/lib/python3.7/site-packages/sqlalchemy/util/compat.py", line 211, in raise_
[2023-05-27T14:02:39.322+0000] {subprocess.py:93} INFO -     raise exception
[2023-05-27T14:02:39.323+0000] {subprocess.py:93} INFO -   File "/home/***/.local/lib/python3.7/site-packages/sqlalchemy/pool/impl.py", line 143, in _do_get
[2023-05-27T14:02:39.323+0000] {subprocess.py:93} INFO -     return self._create_connection()
[2023-05-27T14:02:39.324+0000] {subprocess.py:93} INFO -   File "/home/***/.local/lib/python3.7/site-packages/sqlalchemy/pool/base.py", line 273, in _create_connection
[2023-05-27T14:02:39.326+0000] {subprocess.py:93} INFO -     return _ConnectionRecord(self)
[2023-05-27T14:02:39.327+0000] {subprocess.py:93} INFO -   File "/home/***/.local/lib/python3.7/site-packages/sqlalchemy/pool/base.py", line 388, in __init__
[2023-05-27T14:02:39.328+0000] {subprocess.py:93} INFO -     self.__connect()
[2023-05-27T14:02:39.329+0000] {subprocess.py:93} INFO -   File "/home/***/.local/lib/python3.7/site-packages/sqlalchemy/pool/base.py", line 691, in __connect
[2023-05-27T14:02:39.330+0000] {subprocess.py:93} INFO -     pool.logger.debug("Error on connect(): %s", e)
[2023-05-27T14:02:39.331+0000] {subprocess.py:93} INFO -   File "/home/***/.local/lib/python3.7/site-packages/sqlalchemy/util/langhelpers.py", line 72, in __exit__
[2023-05-27T14:02:39.331+0000] {subprocess.py:93} INFO -     with_traceback=exc_tb,
[2023-05-27T14:02:39.332+0000] {subprocess.py:93} INFO -   File "/home/***/.local/lib/python3.7/site-packages/sqlalchemy/util/compat.py", line 211, in raise_
[2023-05-27T14:02:39.333+0000] {subprocess.py:93} INFO -     raise exception
[2023-05-27T14:02:39.334+0000] {subprocess.py:93} INFO -   File "/home/***/.local/lib/python3.7/site-packages/sqlalchemy/pool/base.py", line 686, in __connect
[2023-05-27T14:02:39.335+0000] {subprocess.py:93} INFO -     self.dbapi_connection = connection = pool._invoke_creator(self)
[2023-05-27T14:02:39.340+0000] {subprocess.py:93} INFO -   File "/home/***/.local/lib/python3.7/site-packages/sqlalchemy/engine/create.py", line 574, in connect
[2023-05-27T14:02:39.342+0000] {subprocess.py:93} INFO -     return dialect.connect(*cargs, **cparams)
[2023-05-27T14:02:39.343+0000] {subprocess.py:93} INFO -   File "/home/***/.local/lib/python3.7/site-packages/sqlalchemy/engine/default.py", line 598, in connect
[2023-05-27T14:02:39.344+0000] {subprocess.py:93} INFO -     return self.dbapi.connect(*cargs, **cparams)
[2023-05-27T14:02:39.345+0000] {subprocess.py:93} INFO -   File "/home/***/.local/lib/python3.7/site-packages/psycopg2/__init__.py", line 122, in connect
[2023-05-27T14:02:39.346+0000] {subprocess.py:93} INFO -     conn = _connect(dsn, connection_factory=connection_factory, **kwasync)
[2023-05-27T14:02:39.347+0000] {subprocess.py:93} INFO - psycopg2.OperationalError: could not translate host name "('postgresLocal'" to address: Name or service not known
[2023-05-27T14:02:39.347+0000] {subprocess.py:93} INFO - could not translate host name ")" to address: Name or service not known
[2023-05-27T14:02:39.348+0000] {subprocess.py:93} INFO - 
[2023-05-27T14:02:39.350+0000] {subprocess.py:93} INFO - 
[2023-05-27T14:02:39.351+0000] {subprocess.py:93} INFO - The above exception was the direct cause of the following exception:
[2023-05-27T14:02:39.355+0000] {subprocess.py:93} INFO - 
[2023-05-27T14:02:39.356+0000] {subprocess.py:93} INFO - Traceback (most recent call last):
[2023-05-27T14:02:39.357+0000] {subprocess.py:93} INFO -   File "/opt/***/dags/load.py", line 15, in <module>
[2023-05-27T14:02:39.357+0000] {subprocess.py:93} INFO -     df.to_sql('final_data', con = engine, if_exists='replace',index_label='id')
[2023-05-27T14:02:39.359+0000] {subprocess.py:93} INFO -   File "/home/***/.local/lib/python3.7/site-packages/pandas/core/generic.py", line 2882, in to_sql
[2023-05-27T14:02:39.360+0000] {subprocess.py:93} INFO -     method=method,
[2023-05-27T14:02:39.361+0000] {subprocess.py:93} INFO -   File "/home/***/.local/lib/python3.7/site-packages/pandas/io/sql.py", line 728, in to_sql
[2023-05-27T14:02:39.361+0000] {subprocess.py:93} INFO -     **engine_kwargs,
[2023-05-27T14:02:39.362+0000] {subprocess.py:93} INFO -   File "/home/***/.local/lib/python3.7/site-packages/pandas/io/sql.py", line 1758, in to_sql
[2023-05-27T14:02:39.363+0000] {subprocess.py:93} INFO -     dtype=dtype,
[2023-05-27T14:02:39.364+0000] {subprocess.py:93} INFO -   File "/home/***/.local/lib/python3.7/site-packages/pandas/io/sql.py", line 1650, in prep_table
[2023-05-27T14:02:39.365+0000] {subprocess.py:93} INFO -     table.create()
[2023-05-27T14:02:39.366+0000] {subprocess.py:93} INFO -   File "/home/***/.local/lib/python3.7/site-packages/pandas/io/sql.py", line 856, in create
[2023-05-27T14:02:39.367+0000] {subprocess.py:93} INFO -     if self.exists():
[2023-05-27T14:02:39.369+0000] {subprocess.py:93} INFO -   File "/home/***/.local/lib/python3.7/site-packages/pandas/io/sql.py", line 840, in exists
[2023-05-27T14:02:39.370+0000] {subprocess.py:93} INFO -     return self.pd_sql.has_table(self.name, self.schema)
[2023-05-27T14:02:39.371+0000] {subprocess.py:93} INFO -   File "/home/***/.local/lib/python3.7/site-packages/pandas/io/sql.py", line 1783, in has_table
[2023-05-27T14:02:39.372+0000] {subprocess.py:93} INFO -     insp = sa.inspect(self.connectable)
[2023-05-27T14:02:39.372+0000] {subprocess.py:93} INFO -   File "/home/***/.local/lib/python3.7/site-packages/sqlalchemy/inspection.py", line 64, in inspect
[2023-05-27T14:02:39.373+0000] {subprocess.py:93} INFO -     ret = reg(subject)
[2023-05-27T14:02:39.374+0000] {subprocess.py:93} INFO -   File "/home/***/.local/lib/python3.7/site-packages/sqlalchemy/engine/reflection.py", line 182, in _engine_insp
[2023-05-27T14:02:39.375+0000] {subprocess.py:93} INFO -     return Inspector._construct(Inspector._init_engine, bind)
[2023-05-27T14:02:39.376+0000] {subprocess.py:93} INFO -   File "/home/***/.local/lib/python3.7/site-packages/sqlalchemy/engine/reflection.py", line 117, in _construct
[2023-05-27T14:02:39.377+0000] {subprocess.py:93} INFO -     init(self, bind)
[2023-05-27T14:02:39.378+0000] {subprocess.py:93} INFO -   File "/home/***/.local/lib/python3.7/site-packages/sqlalchemy/engine/reflection.py", line 128, in _init_engine
[2023-05-27T14:02:39.378+0000] {subprocess.py:93} INFO -     engine.connect().close()
[2023-05-27T14:02:39.379+0000] {subprocess.py:93} INFO -   File "/home/***/.local/lib/python3.7/site-packages/sqlalchemy/engine/base.py", line 3320, in connect
[2023-05-27T14:02:39.379+0000] {subprocess.py:93} INFO -     return self._connection_cls(self, close_with_result=close_with_result)
[2023-05-27T14:02:39.380+0000] {subprocess.py:93} INFO -   File "/home/***/.local/lib/python3.7/site-packages/sqlalchemy/engine/base.py", line 96, in __init__
[2023-05-27T14:02:39.380+0000] {subprocess.py:93} INFO -     else engine.raw_connection()
[2023-05-27T14:02:39.381+0000] {subprocess.py:93} INFO -   File "/home/***/.local/lib/python3.7/site-packages/sqlalchemy/engine/base.py", line 3399, in raw_connection
[2023-05-27T14:02:39.381+0000] {subprocess.py:93} INFO -     return self._wrap_pool_connect(self.pool.connect, _connection)
[2023-05-27T14:02:39.382+0000] {subprocess.py:93} INFO -   File "/home/***/.local/lib/python3.7/site-packages/sqlalchemy/engine/base.py", line 3370, in _wrap_pool_connect
[2023-05-27T14:02:39.383+0000] {subprocess.py:93} INFO -     e, dialect, self
[2023-05-27T14:02:39.384+0000] {subprocess.py:93} INFO -   File "/home/***/.local/lib/python3.7/site-packages/sqlalchemy/engine/base.py", line 2204, in _handle_dbapi_exception_noconnection
[2023-05-27T14:02:39.385+0000] {subprocess.py:93} INFO -     sqlalchemy_exception, with_traceback=exc_info[2], from_=e
[2023-05-27T14:02:39.386+0000] {subprocess.py:93} INFO -   File "/home/***/.local/lib/python3.7/site-packages/sqlalchemy/util/compat.py", line 211, in raise_
[2023-05-27T14:02:39.387+0000] {subprocess.py:93} INFO -     raise exception
[2023-05-27T14:02:39.388+0000] {subprocess.py:93} INFO -   File "/home/***/.local/lib/python3.7/site-packages/sqlalchemy/engine/base.py", line 3366, in _wrap_pool_connect
[2023-05-27T14:02:39.389+0000] {subprocess.py:93} INFO -     return fn()
[2023-05-27T14:02:39.390+0000] {subprocess.py:93} INFO -   File "/home/***/.local/lib/python3.7/site-packages/sqlalchemy/pool/base.py", line 327, in connect
[2023-05-27T14:02:39.392+0000] {subprocess.py:93} INFO -     return _ConnectionFairy._checkout(self)
[2023-05-27T14:02:39.393+0000] {subprocess.py:93} INFO -   File "/home/***/.local/lib/python3.7/site-packages/sqlalchemy/pool/base.py", line 894, in _checkout
[2023-05-27T14:02:39.394+0000] {subprocess.py:93} INFO -     fairy = _ConnectionRecord.checkout(pool)
[2023-05-27T14:02:39.394+0000] {subprocess.py:93} INFO -   File "/home/***/.local/lib/python3.7/site-packages/sqlalchemy/pool/base.py", line 493, in checkout
[2023-05-27T14:02:39.395+0000] {subprocess.py:93} INFO -     rec = pool._do_get()
[2023-05-27T14:02:39.395+0000] {subprocess.py:93} INFO -   File "/home/***/.local/lib/python3.7/site-packages/sqlalchemy/pool/impl.py", line 146, in _do_get
[2023-05-27T14:02:39.396+0000] {subprocess.py:93} INFO -     self._dec_overflow()
[2023-05-27T14:02:39.396+0000] {subprocess.py:93} INFO -   File "/home/***/.local/lib/python3.7/site-packages/sqlalchemy/util/langhelpers.py", line 72, in __exit__
[2023-05-27T14:02:39.397+0000] {subprocess.py:93} INFO -     with_traceback=exc_tb,
[2023-05-27T14:02:39.397+0000] {subprocess.py:93} INFO -   File "/home/***/.local/lib/python3.7/site-packages/sqlalchemy/util/compat.py", line 211, in raise_
[2023-05-27T14:02:39.398+0000] {subprocess.py:93} INFO -     raise exception
[2023-05-27T14:02:39.398+0000] {subprocess.py:93} INFO -   File "/home/***/.local/lib/python3.7/site-packages/sqlalchemy/pool/impl.py", line 143, in _do_get
[2023-05-27T14:02:39.399+0000] {subprocess.py:93} INFO -     return self._create_connection()
[2023-05-27T14:02:39.399+0000] {subprocess.py:93} INFO -   File "/home/***/.local/lib/python3.7/site-packages/sqlalchemy/pool/base.py", line 273, in _create_connection
[2023-05-27T14:02:39.400+0000] {subprocess.py:93} INFO -     return _ConnectionRecord(self)
[2023-05-27T14:02:39.401+0000] {subprocess.py:93} INFO -   File "/home/***/.local/lib/python3.7/site-packages/sqlalchemy/pool/base.py", line 388, in __init__
[2023-05-27T14:02:39.402+0000] {subprocess.py:93} INFO -     self.__connect()
[2023-05-27T14:02:39.403+0000] {subprocess.py:93} INFO -   File "/home/***/.local/lib/python3.7/site-packages/sqlalchemy/pool/base.py", line 691, in __connect
[2023-05-27T14:02:39.404+0000] {subprocess.py:93} INFO -     pool.logger.debug("Error on connect(): %s", e)
[2023-05-27T14:02:39.405+0000] {subprocess.py:93} INFO -   File "/home/***/.local/lib/python3.7/site-packages/sqlalchemy/util/langhelpers.py", line 72, in __exit__
[2023-05-27T14:02:39.406+0000] {subprocess.py:93} INFO -     with_traceback=exc_tb,
[2023-05-27T14:02:39.407+0000] {subprocess.py:93} INFO -   File "/home/***/.local/lib/python3.7/site-packages/sqlalchemy/util/compat.py", line 211, in raise_
[2023-05-27T14:02:39.408+0000] {subprocess.py:93} INFO -     raise exception
[2023-05-27T14:02:39.409+0000] {subprocess.py:93} INFO -   File "/home/***/.local/lib/python3.7/site-packages/sqlalchemy/pool/base.py", line 686, in __connect
[2023-05-27T14:02:39.410+0000] {subprocess.py:93} INFO -     self.dbapi_connection = connection = pool._invoke_creator(self)
[2023-05-27T14:02:39.411+0000] {subprocess.py:93} INFO -   File "/home/***/.local/lib/python3.7/site-packages/sqlalchemy/engine/create.py", line 574, in connect
[2023-05-27T14:02:39.412+0000] {subprocess.py:93} INFO -     return dialect.connect(*cargs, **cparams)
[2023-05-27T14:02:39.413+0000] {subprocess.py:93} INFO -   File "/home/***/.local/lib/python3.7/site-packages/sqlalchemy/engine/default.py", line 598, in connect
[2023-05-27T14:02:39.413+0000] {subprocess.py:93} INFO -     return self.dbapi.connect(*cargs, **cparams)
[2023-05-27T14:02:39.414+0000] {subprocess.py:93} INFO -   File "/home/***/.local/lib/python3.7/site-packages/psycopg2/__init__.py", line 122, in connect
[2023-05-27T14:02:39.415+0000] {subprocess.py:93} INFO -     conn = _connect(dsn, connection_factory=connection_factory, **kwasync)
[2023-05-27T14:02:39.415+0000] {subprocess.py:93} INFO - sqlalchemy.exc.OperationalError: (psycopg2.OperationalError) could not translate host name "('postgresLocal'" to address: Name or service not known
[2023-05-27T14:02:39.416+0000] {subprocess.py:93} INFO - could not translate host name ")" to address: Name or service not known
[2023-05-27T14:02:39.417+0000] {subprocess.py:93} INFO - 
[2023-05-27T14:02:39.418+0000] {subprocess.py:93} INFO - (Background on this error at: https://sqlalche.me/e/14/e3q8)
[2023-05-27T14:02:39.502+0000] {subprocess.py:97} INFO - Command exited with return code 1
[2023-05-27T14:02:39.517+0000] {taskinstance.py:1824} ERROR - Task failed with exception
Traceback (most recent call last):
  File "/home/airflow/.local/lib/python3.7/site-packages/airflow/operators/bash.py", line 211, in execute
    f"Bash command failed. The command returned a non-zero exit code {result.exit_code}."
airflow.exceptions.AirflowException: Bash command failed. The command returned a non-zero exit code 1.
[2023-05-27T14:02:39.523+0000] {taskinstance.py:1350} INFO - Marking task as FAILED. dag_id=my_dag, task_id=Load, execution_date=20230527T135646, start_date=20230527T140236, end_date=20230527T140239
[2023-05-27T14:02:39.550+0000] {standard_task_runner.py:109} ERROR - Failed to execute job 150 for task Load (Bash command failed. The command returned a non-zero exit code 1.; 164)
[2023-05-27T14:02:39.575+0000] {local_task_job_runner.py:225} INFO - Task exited with return code 1
[2023-05-27T14:02:39.608+0000] {taskinstance.py:2651} INFO - 0 downstream tasks scheduled from follow-on schedule check
