[2023-05-31T04:18:49.220+0000] {taskinstance.py:1103} INFO - Dependencies all met for dep_context=non-requeueable deps ti=<TaskInstance: my_dag.Hello manual__2023-05-31T04:18:38.004351+00:00 [queued]>
[2023-05-31T04:18:49.285+0000] {taskinstance.py:1103} INFO - Dependencies all met for dep_context=requeueable deps ti=<TaskInstance: my_dag.Hello manual__2023-05-31T04:18:38.004351+00:00 [queued]>
[2023-05-31T04:18:49.287+0000] {taskinstance.py:1308} INFO - Starting attempt 1 of 1
[2023-05-31T04:18:49.357+0000] {taskinstance.py:1327} INFO - Executing <Task(DockerOperator): Hello> on 2023-05-31 04:18:38.004351+00:00
[2023-05-31T04:18:49.402+0000] {standard_task_runner.py:57} INFO - Started process 95 to run task
[2023-05-31T04:18:49.413+0000] {standard_task_runner.py:84} INFO - Running: ['***', 'tasks', 'run', 'my_dag', 'Hello', 'manual__2023-05-31T04:18:38.004351+00:00', '--job-id', '26', '--raw', '--subdir', 'DAGS_FOLDER/my_dag.py', '--cfg-path', '/tmp/tmpsh91rj86']
[2023-05-31T04:18:49.420+0000] {standard_task_runner.py:85} INFO - Job 26: Subtask Hello
[2023-05-31T04:18:49.626+0000] {task_command.py:410} INFO - Running <TaskInstance: my_dag.Hello manual__2023-05-31T04:18:38.004351+00:00 [running]> on host e578fc747af9
[2023-05-31T04:18:49.921+0000] {taskinstance.py:1547} INFO - Exporting env vars: AIRFLOW_CTX_DAG_OWNER='***' AIRFLOW_CTX_DAG_ID='my_dag' AIRFLOW_CTX_TASK_ID='Hello' AIRFLOW_CTX_EXECUTION_DATE='2023-05-31T04:18:38.004351+00:00' AIRFLOW_CTX_TRY_NUMBER='1' AIRFLOW_CTX_DAG_RUN_ID='manual__2023-05-31T04:18:38.004351+00:00'
[2023-05-31T04:18:50.038+0000] {docker.py:324} INFO - Starting docker container from image my_etl:test
[2023-05-31T04:18:50.127+0000] {docker.py:333} WARNING - Using remote engine or docker-in-docker and mounting temporary volume from host is not supported. Falling back to `mount_tmp_dir=False` mode. You can set `mount_tmp_dir` parameter to False to disable mounting and remove the warning
[2023-05-31T04:18:51.788+0000] {docker.py:391} INFO - python: can't open file '/app/docker/Hello.py': [Errno 2] No such file or directory
[2023-05-31T04:18:52.513+0000] {taskinstance.py:1824} ERROR - Task failed with exception
Traceback (most recent call last):
  File "/home/airflow/.local/lib/python3.7/site-packages/docker/api/client.py", line 268, in _raise_for_status
    response.raise_for_status()
  File "/home/airflow/.local/lib/python3.7/site-packages/requests/models.py", line 1021, in raise_for_status
    raise HTTPError(http_error_msg, response=self)
requests.exceptions.HTTPError: 400 Client Error: Bad Request for url: http://docker-proxy:2375/v1.42/containers/create

The above exception was the direct cause of the following exception:

Traceback (most recent call last):
  File "/home/airflow/.local/lib/python3.7/site-packages/airflow/providers/docker/operators/docker.py", line 329, in _run_image
    return self._run_image_with_mounts(self.mounts + [tmp_mount], add_tmp_variable=True)
  File "/home/airflow/.local/lib/python3.7/site-packages/airflow/providers/docker/operators/docker.py", line 381, in _run_image_with_mounts
    hostname=self.hostname,
  File "/home/airflow/.local/lib/python3.7/site-packages/docker/api/container.py", line 431, in create_container
    return self.create_container_from_config(config, name, platform)
  File "/home/airflow/.local/lib/python3.7/site-packages/docker/api/container.py", line 448, in create_container_from_config
    return self._result(res, True)
  File "/home/airflow/.local/lib/python3.7/site-packages/docker/api/client.py", line 274, in _result
    self._raise_for_status(response)
  File "/home/airflow/.local/lib/python3.7/site-packages/docker/api/client.py", line 270, in _raise_for_status
    raise create_api_error_from_http_exception(e) from e
  File "/home/airflow/.local/lib/python3.7/site-packages/docker/errors.py", line 39, in create_api_error_from_http_exception
    raise cls(e, response=response, explanation=explanation) from e
docker.errors.APIError: 400 Client Error for http://docker-proxy:2375/v1.42/containers/create: Bad Request ("invalid mount config for type "bind": bind source path does not exist: /tmp/airflowtmpscuaq_ky")

During handling of the above exception, another exception occurred:

Traceback (most recent call last):
  File "/home/airflow/.local/lib/python3.7/site-packages/airflow/providers/docker/operators/docker.py", line 466, in execute
    return self._run_image()
  File "/home/airflow/.local/lib/python3.7/site-packages/airflow/providers/docker/operators/docker.py", line 338, in _run_image
    return self._run_image_with_mounts(self.mounts, add_tmp_variable=False)
  File "/home/airflow/.local/lib/python3.7/site-packages/airflow/providers/docker/operators/docker.py", line 400, in _run_image_with_mounts
    raise AirflowException(f"Docker container failed: {repr(result)} lines {joined_log_lines}")
airflow.exceptions.AirflowException: Docker container failed: {'StatusCode': 2} lines python: can't open file '/app/docker/Hello.py': [Errno 2] No such file or directory
[2023-05-31T04:18:52.531+0000] {taskinstance.py:1350} INFO - Marking task as FAILED. dag_id=my_dag, task_id=Hello, execution_date=20230531T041838, start_date=20230531T041849, end_date=20230531T041852
[2023-05-31T04:18:52.577+0000] {standard_task_runner.py:109} ERROR - Failed to execute job 26 for task Hello (Docker container failed: {'StatusCode': 2} lines python: can't open file '/app/docker/Hello.py': [Errno 2] No such file or directory; 95)
[2023-05-31T04:18:52.620+0000] {local_task_job_runner.py:225} INFO - Task exited with return code 1
[2023-05-31T04:18:52.709+0000] {taskinstance.py:2651} INFO - 0 downstream tasks scheduled from follow-on schedule check
