[2023-06-02T02:22:31.234+0000] {taskinstance.py:1103} INFO - Dependencies all met for dep_context=non-requeueable deps ti=<TaskInstance: my_dag.transform manual__2023-06-02T02:22:21.836717+00:00 [queued]>
[2023-06-02T02:22:31.257+0000] {taskinstance.py:1103} INFO - Dependencies all met for dep_context=requeueable deps ti=<TaskInstance: my_dag.transform manual__2023-06-02T02:22:21.836717+00:00 [queued]>
[2023-06-02T02:22:31.258+0000] {taskinstance.py:1308} INFO - Starting attempt 1 of 1
[2023-06-02T02:22:31.282+0000] {taskinstance.py:1327} INFO - Executing <Task(DockerOperator): transform> on 2023-06-02 02:22:21.836717+00:00
[2023-06-02T02:22:31.291+0000] {standard_task_runner.py:57} INFO - Started process 232 to run task
[2023-06-02T02:22:31.294+0000] {standard_task_runner.py:84} INFO - Running: ['***', 'tasks', 'run', 'my_dag', 'transform', 'manual__2023-06-02T02:22:21.836717+00:00', '--job-id', '62', '--raw', '--subdir', 'DAGS_FOLDER/my_dag.py', '--cfg-path', '/tmp/tmpkg9il23g']
[2023-06-02T02:22:31.297+0000] {standard_task_runner.py:85} INFO - Job 62: Subtask transform
[2023-06-02T02:22:31.361+0000] {task_command.py:410} INFO - Running <TaskInstance: my_dag.transform manual__2023-06-02T02:22:21.836717+00:00 [running]> on host 494051a68f2e
[2023-06-02T02:22:31.496+0000] {taskinstance.py:1547} INFO - Exporting env vars: AIRFLOW_CTX_DAG_OWNER='***' AIRFLOW_CTX_DAG_ID='my_dag' AIRFLOW_CTX_TASK_ID='transform' AIRFLOW_CTX_EXECUTION_DATE='2023-06-02T02:22:21.836717+00:00' AIRFLOW_CTX_TRY_NUMBER='1' AIRFLOW_CTX_DAG_RUN_ID='manual__2023-06-02T02:22:21.836717+00:00'
[2023-06-02T02:22:31.538+0000] {docker.py:324} INFO - Starting docker container from image my_etl:transform
[2023-06-02T02:22:32.277+0000] {docker.py:391} INFO - python: can't open file '/app/transform.py': [Errno 2] No such file or directory
[2023-06-02T02:22:32.672+0000] {taskinstance.py:1824} ERROR - Task failed with exception
Traceback (most recent call last):
  File "/home/airflow/.local/lib/python3.7/site-packages/airflow/providers/docker/operators/docker.py", line 466, in execute
    return self._run_image()
  File "/home/airflow/.local/lib/python3.7/site-packages/airflow/providers/docker/operators/docker.py", line 341, in _run_image
    return self._run_image_with_mounts(self.mounts, add_tmp_variable=False)
  File "/home/airflow/.local/lib/python3.7/site-packages/airflow/providers/docker/operators/docker.py", line 400, in _run_image_with_mounts
    raise AirflowException(f"Docker container failed: {repr(result)} lines {joined_log_lines}")
airflow.exceptions.AirflowException: Docker container failed: {'StatusCode': 2} lines python: can't open file '/app/transform.py': [Errno 2] No such file or directory
[2023-06-02T02:22:32.679+0000] {taskinstance.py:1350} INFO - Marking task as FAILED. dag_id=my_dag, task_id=transform, execution_date=20230602T022221, start_date=20230602T022231, end_date=20230602T022232
[2023-06-02T02:22:32.705+0000] {standard_task_runner.py:109} ERROR - Failed to execute job 62 for task transform (Docker container failed: {'StatusCode': 2} lines python: can't open file '/app/transform.py': [Errno 2] No such file or directory; 232)
[2023-06-02T02:22:32.754+0000] {local_task_job_runner.py:225} INFO - Task exited with return code 1
[2023-06-02T02:22:32.832+0000] {taskinstance.py:2651} INFO - 0 downstream tasks scheduled from follow-on schedule check
