[2023-06-01T08:58:03.080+0000] {taskinstance.py:1103} INFO - Dependencies all met for dep_context=non-requeueable deps ti=<TaskInstance: my_dag.load manual__2023-06-01T08:55:51.064391+00:00 [queued]>
[2023-06-01T08:58:03.096+0000] {taskinstance.py:1103} INFO - Dependencies all met for dep_context=requeueable deps ti=<TaskInstance: my_dag.load manual__2023-06-01T08:55:51.064391+00:00 [queued]>
[2023-06-01T08:58:03.096+0000] {taskinstance.py:1308} INFO - Starting attempt 1 of 1
[2023-06-01T08:58:03.120+0000] {taskinstance.py:1327} INFO - Executing <Task(DockerOperator): load> on 2023-06-01 08:55:51.064391+00:00
[2023-06-01T08:58:03.129+0000] {standard_task_runner.py:57} INFO - Started process 1282 to run task
[2023-06-01T08:58:03.134+0000] {standard_task_runner.py:84} INFO - Running: ['***', 'tasks', 'run', 'my_dag', 'load', 'manual__2023-06-01T08:55:51.064391+00:00', '--job-id', '35', '--raw', '--subdir', 'DAGS_FOLDER/my_dag.py', '--cfg-path', '/tmp/tmpchi_9mkh']
[2023-06-01T08:58:03.137+0000] {standard_task_runner.py:85} INFO - Job 35: Subtask load
[2023-06-01T08:58:03.208+0000] {task_command.py:410} INFO - Running <TaskInstance: my_dag.load manual__2023-06-01T08:55:51.064391+00:00 [running]> on host 6bccebd655ed
[2023-06-01T08:58:03.373+0000] {taskinstance.py:1547} INFO - Exporting env vars: AIRFLOW_CTX_DAG_OWNER='***' AIRFLOW_CTX_DAG_ID='my_dag' AIRFLOW_CTX_TASK_ID='load' AIRFLOW_CTX_EXECUTION_DATE='2023-06-01T08:55:51.064391+00:00' AIRFLOW_CTX_TRY_NUMBER='1' AIRFLOW_CTX_DAG_RUN_ID='manual__2023-06-01T08:55:51.064391+00:00'
[2023-06-01T08:58:03.439+0000] {docker.py:324} INFO - Starting docker container from image my_etl:load
[2023-06-01T08:58:05.679+0000] {docker.py:391} INFO - Traceback (most recent call last):
  File "/app/load.py", line 15, in <module>
    df = pd.read_sql_table('stating_data',con = engine,schema="public",columns=["First Name","Last name","Age","Sex"])
  File "/usr/local/lib/python3.9/site-packages/pandas/io/sql.py", line 289, in read_sql_table
[2023-06-01T08:58:05.681+0000] {docker.py:391} INFO - table = pandas_sql.read_table(
  File "/usr/local/lib/python3.9/site-packages/pandas/io/sql.py", line 1460, in read_table
[2023-06-01T08:58:05.682+0000] {docker.py:391} INFO - return table.read(
  File "/usr/local/lib/python3.9/site-packages/pandas/io/sql.py", line 995, in read
[2023-06-01T08:58:05.683+0000] {docker.py:391} INFO - cols = [self.table.c[n] for n in columns]
  File "/usr/local/lib/python3.9/site-packages/pandas/io/sql.py", line 995, in <listcomp>
[2023-06-01T08:58:05.684+0000] {docker.py:391} INFO - cols = [self.table.c[n] for n in columns]
  File "/usr/local/lib/python3.9/site-packages/sqlalchemy/sql/base.py", line 1214, in __getitem__
[2023-06-01T08:58:05.685+0000] {docker.py:391} INFO - return self._index[key]
KeyError: 'Last name'
[2023-06-01T08:58:06.238+0000] {taskinstance.py:1824} ERROR - Task failed with exception
Traceback (most recent call last):
  File "/home/airflow/.local/lib/python3.7/site-packages/airflow/providers/docker/operators/docker.py", line 466, in execute
    return self._run_image()
  File "/home/airflow/.local/lib/python3.7/site-packages/airflow/providers/docker/operators/docker.py", line 341, in _run_image
    return self._run_image_with_mounts(self.mounts, add_tmp_variable=False)
  File "/home/airflow/.local/lib/python3.7/site-packages/airflow/providers/docker/operators/docker.py", line 400, in _run_image_with_mounts
    raise AirflowException(f"Docker container failed: {repr(result)} lines {joined_log_lines}")
airflow.exceptions.AirflowException: Docker container failed: {'StatusCode': 1} lines Traceback (most recent call last):
  File "/app/load.py", line 15, in <module>
    df = pd.read_sql_table('stating_data',con = engine,schema="public",columns=["First Name","Last name","Age","Sex"])
  File "/usr/local/lib/python3.9/site-packages/pandas/io/sql.py", line 289, in read_sql_table
table = pandas_sql.read_table(
  File "/usr/local/lib/python3.9/site-packages/pandas/io/sql.py", line 1460, in read_table
return table.read(
  File "/usr/local/lib/python3.9/site-packages/pandas/io/sql.py", line 995, in read
cols = [self.table.c[n] for n in columns]
  File "/usr/local/lib/python3.9/site-packages/pandas/io/sql.py", line 995, in <listcomp>
cols = [self.table.c[n] for n in columns]
  File "/usr/local/lib/python3.9/site-packages/sqlalchemy/sql/base.py", line 1214, in __getitem__
return self._index[key]
KeyError: 'Last name'
[2023-06-01T08:58:06.246+0000] {taskinstance.py:1350} INFO - Marking task as FAILED. dag_id=my_dag, task_id=load, execution_date=20230601T085551, start_date=20230601T085803, end_date=20230601T085806
[2023-06-01T08:58:06.276+0000] {standard_task_runner.py:109} ERROR - Failed to execute job 35 for task load (Docker container failed: {'StatusCode': 1} lines Traceback (most recent call last):
  File "/app/load.py", line 15, in <module>
    df = pd.read_sql_table('stating_data',con = engine,schema="public",columns=["First Name","Last name","Age","Sex"])
  File "/usr/local/lib/python3.9/site-packages/pandas/io/sql.py", line 289, in read_sql_table
table = pandas_sql.read_table(
  File "/usr/local/lib/python3.9/site-packages/pandas/io/sql.py", line 1460, in read_table
return table.read(
  File "/usr/local/lib/python3.9/site-packages/pandas/io/sql.py", line 995, in read
cols = [self.table.c[n] for n in columns]
  File "/usr/local/lib/python3.9/site-packages/pandas/io/sql.py", line 995, in <listcomp>
cols = [self.table.c[n] for n in columns]
  File "/usr/local/lib/python3.9/site-packages/sqlalchemy/sql/base.py", line 1214, in __getitem__
return self._index[key]
KeyError: 'Last name'; 1282)
[2023-06-01T08:58:06.339+0000] {local_task_job_runner.py:225} INFO - Task exited with return code 1
[2023-06-01T08:58:06.374+0000] {taskinstance.py:2651} INFO - 0 downstream tasks scheduled from follow-on schedule check
