[2023-05-26T01:40:02.470+0000] {taskinstance.py:1103} INFO - Dependencies all met for dep_context=non-requeueable deps ti=<TaskInstance: my_dag.Load manual__2023-05-26T01:39:36.452579+00:00 [queued]>
[2023-05-26T01:40:02.485+0000] {taskinstance.py:1103} INFO - Dependencies all met for dep_context=requeueable deps ti=<TaskInstance: my_dag.Load manual__2023-05-26T01:39:36.452579+00:00 [queued]>
[2023-05-26T01:40:02.486+0000] {taskinstance.py:1308} INFO - Starting attempt 1 of 1
[2023-05-26T01:40:02.508+0000] {taskinstance.py:1327} INFO - Executing <Task(BashOperator): Load> on 2023-05-26 01:39:36.452579+00:00
[2023-05-26T01:40:02.515+0000] {standard_task_runner.py:57} INFO - Started process 600 to run task
[2023-05-26T01:40:02.518+0000] {standard_task_runner.py:84} INFO - Running: ['***', 'tasks', 'run', 'my_dag', 'Load', 'manual__2023-05-26T01:39:36.452579+00:00', '--job-id', '128', '--raw', '--subdir', 'DAGS_FOLDER/my_dag.py', '--cfg-path', '/tmp/tmphqxi5le_']
[2023-05-26T01:40:02.521+0000] {standard_task_runner.py:85} INFO - Job 128: Subtask Load
[2023-05-26T01:40:02.576+0000] {task_command.py:410} INFO - Running <TaskInstance: my_dag.Load manual__2023-05-26T01:39:36.452579+00:00 [running]> on host b4633f3f51cb
[2023-05-26T01:40:02.689+0000] {taskinstance.py:1547} INFO - Exporting env vars: AIRFLOW_CTX_DAG_OWNER='***' AIRFLOW_CTX_DAG_ID='my_dag' AIRFLOW_CTX_TASK_ID='Load' AIRFLOW_CTX_EXECUTION_DATE='2023-05-26T01:39:36.452579+00:00' AIRFLOW_CTX_TRY_NUMBER='1' AIRFLOW_CTX_DAG_RUN_ID='manual__2023-05-26T01:39:36.452579+00:00'
[2023-05-26T01:40:02.692+0000] {subprocess.py:63} INFO - Tmp dir root location: 
 /tmp
[2023-05-26T01:40:02.693+0000] {subprocess.py:75} INFO - Running command: ['/bin/bash', '-c', 'python /opt/***/dags/load.py']
[2023-05-26T01:40:02.706+0000] {subprocess.py:86} INFO - Output:
[2023-05-26T01:40:04.626+0000] {subprocess.py:93} INFO - Traceback (most recent call last):
[2023-05-26T01:40:04.628+0000] {subprocess.py:93} INFO -   File "/home/***/.local/lib/python3.7/site-packages/sqlalchemy/engine/base.py", line 3366, in _wrap_pool_connect
[2023-05-26T01:40:04.629+0000] {subprocess.py:93} INFO -     return fn()
[2023-05-26T01:40:04.631+0000] {subprocess.py:93} INFO -   File "/home/***/.local/lib/python3.7/site-packages/sqlalchemy/pool/base.py", line 327, in connect
[2023-05-26T01:40:04.631+0000] {subprocess.py:93} INFO -     return _ConnectionFairy._checkout(self)
[2023-05-26T01:40:04.632+0000] {subprocess.py:93} INFO -   File "/home/***/.local/lib/python3.7/site-packages/sqlalchemy/pool/base.py", line 894, in _checkout
[2023-05-26T01:40:04.633+0000] {subprocess.py:93} INFO -     fairy = _ConnectionRecord.checkout(pool)
[2023-05-26T01:40:04.634+0000] {subprocess.py:93} INFO -   File "/home/***/.local/lib/python3.7/site-packages/sqlalchemy/pool/base.py", line 493, in checkout
[2023-05-26T01:40:04.635+0000] {subprocess.py:93} INFO -     rec = pool._do_get()
[2023-05-26T01:40:04.636+0000] {subprocess.py:93} INFO -   File "/home/***/.local/lib/python3.7/site-packages/sqlalchemy/pool/impl.py", line 146, in _do_get
[2023-05-26T01:40:04.637+0000] {subprocess.py:93} INFO -     self._dec_overflow()
[2023-05-26T01:40:04.638+0000] {subprocess.py:93} INFO -   File "/home/***/.local/lib/python3.7/site-packages/sqlalchemy/util/langhelpers.py", line 72, in __exit__
[2023-05-26T01:40:04.638+0000] {subprocess.py:93} INFO -     with_traceback=exc_tb,
[2023-05-26T01:40:04.639+0000] {subprocess.py:93} INFO -   File "/home/***/.local/lib/python3.7/site-packages/sqlalchemy/util/compat.py", line 211, in raise_
[2023-05-26T01:40:04.640+0000] {subprocess.py:93} INFO -     raise exception
[2023-05-26T01:40:04.640+0000] {subprocess.py:93} INFO -   File "/home/***/.local/lib/python3.7/site-packages/sqlalchemy/pool/impl.py", line 143, in _do_get
[2023-05-26T01:40:04.641+0000] {subprocess.py:93} INFO -     return self._create_connection()
[2023-05-26T01:40:04.642+0000] {subprocess.py:93} INFO -   File "/home/***/.local/lib/python3.7/site-packages/sqlalchemy/pool/base.py", line 273, in _create_connection
[2023-05-26T01:40:04.643+0000] {subprocess.py:93} INFO -     return _ConnectionRecord(self)
[2023-05-26T01:40:04.644+0000] {subprocess.py:93} INFO -   File "/home/***/.local/lib/python3.7/site-packages/sqlalchemy/pool/base.py", line 388, in __init__
[2023-05-26T01:40:04.645+0000] {subprocess.py:93} INFO -     self.__connect()
[2023-05-26T01:40:04.646+0000] {subprocess.py:93} INFO -   File "/home/***/.local/lib/python3.7/site-packages/sqlalchemy/pool/base.py", line 691, in __connect
[2023-05-26T01:40:04.646+0000] {subprocess.py:93} INFO -     pool.logger.debug("Error on connect(): %s", e)
[2023-05-26T01:40:04.647+0000] {subprocess.py:93} INFO -   File "/home/***/.local/lib/python3.7/site-packages/sqlalchemy/util/langhelpers.py", line 72, in __exit__
[2023-05-26T01:40:04.648+0000] {subprocess.py:93} INFO -     with_traceback=exc_tb,
[2023-05-26T01:40:04.648+0000] {subprocess.py:93} INFO -   File "/home/***/.local/lib/python3.7/site-packages/sqlalchemy/util/compat.py", line 211, in raise_
[2023-05-26T01:40:04.649+0000] {subprocess.py:93} INFO -     raise exception
[2023-05-26T01:40:04.649+0000] {subprocess.py:93} INFO -   File "/home/***/.local/lib/python3.7/site-packages/sqlalchemy/pool/base.py", line 686, in __connect
[2023-05-26T01:40:04.651+0000] {subprocess.py:93} INFO -     self.dbapi_connection = connection = pool._invoke_creator(self)
[2023-05-26T01:40:04.652+0000] {subprocess.py:93} INFO -   File "/home/***/.local/lib/python3.7/site-packages/sqlalchemy/engine/create.py", line 574, in connect
[2023-05-26T01:40:04.653+0000] {subprocess.py:93} INFO -     return dialect.connect(*cargs, **cparams)
[2023-05-26T01:40:04.654+0000] {subprocess.py:93} INFO -   File "/home/***/.local/lib/python3.7/site-packages/sqlalchemy/engine/default.py", line 598, in connect
[2023-05-26T01:40:04.654+0000] {subprocess.py:93} INFO -     return self.dbapi.connect(*cargs, **cparams)
[2023-05-26T01:40:04.655+0000] {subprocess.py:93} INFO -   File "/home/***/.local/lib/python3.7/site-packages/psycopg2/__init__.py", line 122, in connect
[2023-05-26T01:40:04.655+0000] {subprocess.py:93} INFO -     conn = _connect(dsn, connection_factory=connection_factory, **kwasync)
[2023-05-26T01:40:04.656+0000] {subprocess.py:93} INFO - psycopg2.OperationalError: could not translate host name "('postgresLocal'" to address: Name or service not known
[2023-05-26T01:40:04.656+0000] {subprocess.py:93} INFO - could not translate host name ")" to address: Name or service not known
[2023-05-26T01:40:04.657+0000] {subprocess.py:93} INFO - 
[2023-05-26T01:40:04.658+0000] {subprocess.py:93} INFO - 
[2023-05-26T01:40:04.661+0000] {subprocess.py:93} INFO - The above exception was the direct cause of the following exception:
[2023-05-26T01:40:04.662+0000] {subprocess.py:93} INFO - 
[2023-05-26T01:40:04.663+0000] {subprocess.py:93} INFO - Traceback (most recent call last):
[2023-05-26T01:40:04.664+0000] {subprocess.py:93} INFO -   File "/opt/***/dags/load.py", line 15, in <module>
[2023-05-26T01:40:04.664+0000] {subprocess.py:93} INFO -     df.to_sql('final_data', con = connectionDB(), if_exists='replace',index_label='id')
[2023-05-26T01:40:04.665+0000] {subprocess.py:93} INFO -   File "/home/***/.local/lib/python3.7/site-packages/pandas/core/generic.py", line 2882, in to_sql
[2023-05-26T01:40:04.665+0000] {subprocess.py:93} INFO -     method=method,
[2023-05-26T01:40:04.666+0000] {subprocess.py:93} INFO -   File "/home/***/.local/lib/python3.7/site-packages/pandas/io/sql.py", line 728, in to_sql
[2023-05-26T01:40:04.666+0000] {subprocess.py:93} INFO -     **engine_kwargs,
[2023-05-26T01:40:04.667+0000] {subprocess.py:93} INFO -   File "/home/***/.local/lib/python3.7/site-packages/pandas/io/sql.py", line 1758, in to_sql
[2023-05-26T01:40:04.667+0000] {subprocess.py:93} INFO -     dtype=dtype,
[2023-05-26T01:40:04.668+0000] {subprocess.py:93} INFO -   File "/home/***/.local/lib/python3.7/site-packages/pandas/io/sql.py", line 1650, in prep_table
[2023-05-26T01:40:04.669+0000] {subprocess.py:93} INFO -     table.create()
[2023-05-26T01:40:04.669+0000] {subprocess.py:93} INFO -   File "/home/***/.local/lib/python3.7/site-packages/pandas/io/sql.py", line 856, in create
[2023-05-26T01:40:04.670+0000] {subprocess.py:93} INFO -     if self.exists():
[2023-05-26T01:40:04.671+0000] {subprocess.py:93} INFO -   File "/home/***/.local/lib/python3.7/site-packages/pandas/io/sql.py", line 840, in exists
[2023-05-26T01:40:04.671+0000] {subprocess.py:93} INFO -     return self.pd_sql.has_table(self.name, self.schema)
[2023-05-26T01:40:04.672+0000] {subprocess.py:93} INFO -   File "/home/***/.local/lib/python3.7/site-packages/pandas/io/sql.py", line 1783, in has_table
[2023-05-26T01:40:04.672+0000] {subprocess.py:93} INFO -     insp = sa.inspect(self.connectable)
[2023-05-26T01:40:04.672+0000] {subprocess.py:93} INFO -   File "/home/***/.local/lib/python3.7/site-packages/sqlalchemy/inspection.py", line 64, in inspect
[2023-05-26T01:40:04.673+0000] {subprocess.py:93} INFO -     ret = reg(subject)
[2023-05-26T01:40:04.673+0000] {subprocess.py:93} INFO -   File "/home/***/.local/lib/python3.7/site-packages/sqlalchemy/engine/reflection.py", line 182, in _engine_insp
[2023-05-26T01:40:04.674+0000] {subprocess.py:93} INFO -     return Inspector._construct(Inspector._init_engine, bind)
[2023-05-26T01:40:04.675+0000] {subprocess.py:93} INFO -   File "/home/***/.local/lib/python3.7/site-packages/sqlalchemy/engine/reflection.py", line 117, in _construct
[2023-05-26T01:40:04.675+0000] {subprocess.py:93} INFO -     init(self, bind)
[2023-05-26T01:40:04.676+0000] {subprocess.py:93} INFO -   File "/home/***/.local/lib/python3.7/site-packages/sqlalchemy/engine/reflection.py", line 128, in _init_engine
[2023-05-26T01:40:04.677+0000] {subprocess.py:93} INFO -     engine.connect().close()
[2023-05-26T01:40:04.677+0000] {subprocess.py:93} INFO -   File "/home/***/.local/lib/python3.7/site-packages/sqlalchemy/engine/base.py", line 3320, in connect
[2023-05-26T01:40:04.678+0000] {subprocess.py:93} INFO -     return self._connection_cls(self, close_with_result=close_with_result)
[2023-05-26T01:40:04.679+0000] {subprocess.py:93} INFO -   File "/home/***/.local/lib/python3.7/site-packages/sqlalchemy/engine/base.py", line 96, in __init__
[2023-05-26T01:40:04.679+0000] {subprocess.py:93} INFO -     else engine.raw_connection()
[2023-05-26T01:40:04.680+0000] {subprocess.py:93} INFO -   File "/home/***/.local/lib/python3.7/site-packages/sqlalchemy/engine/base.py", line 3399, in raw_connection
[2023-05-26T01:40:04.680+0000] {subprocess.py:93} INFO -     return self._wrap_pool_connect(self.pool.connect, _connection)
[2023-05-26T01:40:04.681+0000] {subprocess.py:93} INFO -   File "/home/***/.local/lib/python3.7/site-packages/sqlalchemy/engine/base.py", line 3370, in _wrap_pool_connect
[2023-05-26T01:40:04.681+0000] {subprocess.py:93} INFO -     e, dialect, self
[2023-05-26T01:40:04.681+0000] {subprocess.py:93} INFO -   File "/home/***/.local/lib/python3.7/site-packages/sqlalchemy/engine/base.py", line 2204, in _handle_dbapi_exception_noconnection
[2023-05-26T01:40:04.682+0000] {subprocess.py:93} INFO -     sqlalchemy_exception, with_traceback=exc_info[2], from_=e
[2023-05-26T01:40:04.682+0000] {subprocess.py:93} INFO -   File "/home/***/.local/lib/python3.7/site-packages/sqlalchemy/util/compat.py", line 211, in raise_
[2023-05-26T01:40:04.682+0000] {subprocess.py:93} INFO -     raise exception
[2023-05-26T01:40:04.683+0000] {subprocess.py:93} INFO -   File "/home/***/.local/lib/python3.7/site-packages/sqlalchemy/engine/base.py", line 3366, in _wrap_pool_connect
[2023-05-26T01:40:04.683+0000] {subprocess.py:93} INFO -     return fn()
[2023-05-26T01:40:04.684+0000] {subprocess.py:93} INFO -   File "/home/***/.local/lib/python3.7/site-packages/sqlalchemy/pool/base.py", line 327, in connect
[2023-05-26T01:40:04.685+0000] {subprocess.py:93} INFO -     return _ConnectionFairy._checkout(self)
[2023-05-26T01:40:04.685+0000] {subprocess.py:93} INFO -   File "/home/***/.local/lib/python3.7/site-packages/sqlalchemy/pool/base.py", line 894, in _checkout
[2023-05-26T01:40:04.686+0000] {subprocess.py:93} INFO -     fairy = _ConnectionRecord.checkout(pool)
[2023-05-26T01:40:04.686+0000] {subprocess.py:93} INFO -   File "/home/***/.local/lib/python3.7/site-packages/sqlalchemy/pool/base.py", line 493, in checkout
[2023-05-26T01:40:04.687+0000] {subprocess.py:93} INFO -     rec = pool._do_get()
[2023-05-26T01:40:04.687+0000] {subprocess.py:93} INFO -   File "/home/***/.local/lib/python3.7/site-packages/sqlalchemy/pool/impl.py", line 146, in _do_get
[2023-05-26T01:40:04.687+0000] {subprocess.py:93} INFO -     self._dec_overflow()
[2023-05-26T01:40:04.688+0000] {subprocess.py:93} INFO -   File "/home/***/.local/lib/python3.7/site-packages/sqlalchemy/util/langhelpers.py", line 72, in __exit__
[2023-05-26T01:40:04.688+0000] {subprocess.py:93} INFO -     with_traceback=exc_tb,
[2023-05-26T01:40:04.689+0000] {subprocess.py:93} INFO -   File "/home/***/.local/lib/python3.7/site-packages/sqlalchemy/util/compat.py", line 211, in raise_
[2023-05-26T01:40:04.689+0000] {subprocess.py:93} INFO -     raise exception
[2023-05-26T01:40:04.689+0000] {subprocess.py:93} INFO -   File "/home/***/.local/lib/python3.7/site-packages/sqlalchemy/pool/impl.py", line 143, in _do_get
[2023-05-26T01:40:04.690+0000] {subprocess.py:93} INFO -     return self._create_connection()
[2023-05-26T01:40:04.690+0000] {subprocess.py:93} INFO -   File "/home/***/.local/lib/python3.7/site-packages/sqlalchemy/pool/base.py", line 273, in _create_connection
[2023-05-26T01:40:04.691+0000] {subprocess.py:93} INFO -     return _ConnectionRecord(self)
[2023-05-26T01:40:04.691+0000] {subprocess.py:93} INFO -   File "/home/***/.local/lib/python3.7/site-packages/sqlalchemy/pool/base.py", line 388, in __init__
[2023-05-26T01:40:04.691+0000] {subprocess.py:93} INFO -     self.__connect()
[2023-05-26T01:40:04.692+0000] {subprocess.py:93} INFO -   File "/home/***/.local/lib/python3.7/site-packages/sqlalchemy/pool/base.py", line 691, in __connect
[2023-05-26T01:40:04.693+0000] {subprocess.py:93} INFO -     pool.logger.debug("Error on connect(): %s", e)
[2023-05-26T01:40:04.693+0000] {subprocess.py:93} INFO -   File "/home/***/.local/lib/python3.7/site-packages/sqlalchemy/util/langhelpers.py", line 72, in __exit__
[2023-05-26T01:40:04.694+0000] {subprocess.py:93} INFO -     with_traceback=exc_tb,
[2023-05-26T01:40:04.695+0000] {subprocess.py:93} INFO -   File "/home/***/.local/lib/python3.7/site-packages/sqlalchemy/util/compat.py", line 211, in raise_
[2023-05-26T01:40:04.695+0000] {subprocess.py:93} INFO -     raise exception
[2023-05-26T01:40:04.695+0000] {subprocess.py:93} INFO -   File "/home/***/.local/lib/python3.7/site-packages/sqlalchemy/pool/base.py", line 686, in __connect
[2023-05-26T01:40:04.696+0000] {subprocess.py:93} INFO -     self.dbapi_connection = connection = pool._invoke_creator(self)
[2023-05-26T01:40:04.696+0000] {subprocess.py:93} INFO -   File "/home/***/.local/lib/python3.7/site-packages/sqlalchemy/engine/create.py", line 574, in connect
[2023-05-26T01:40:04.697+0000] {subprocess.py:93} INFO -     return dialect.connect(*cargs, **cparams)
[2023-05-26T01:40:04.697+0000] {subprocess.py:93} INFO -   File "/home/***/.local/lib/python3.7/site-packages/sqlalchemy/engine/default.py", line 598, in connect
[2023-05-26T01:40:04.698+0000] {subprocess.py:93} INFO -     return self.dbapi.connect(*cargs, **cparams)
[2023-05-26T01:40:04.698+0000] {subprocess.py:93} INFO -   File "/home/***/.local/lib/python3.7/site-packages/psycopg2/__init__.py", line 122, in connect
[2023-05-26T01:40:04.699+0000] {subprocess.py:93} INFO -     conn = _connect(dsn, connection_factory=connection_factory, **kwasync)
[2023-05-26T01:40:04.699+0000] {subprocess.py:93} INFO - sqlalchemy.exc.OperationalError: (psycopg2.OperationalError) could not translate host name "('postgresLocal'" to address: Name or service not known
[2023-05-26T01:40:04.700+0000] {subprocess.py:93} INFO - could not translate host name ")" to address: Name or service not known
[2023-05-26T01:40:04.701+0000] {subprocess.py:93} INFO - 
[2023-05-26T01:40:04.702+0000] {subprocess.py:93} INFO - (Background on this error at: https://sqlalche.me/e/14/e3q8)
[2023-05-26T01:40:04.766+0000] {subprocess.py:97} INFO - Command exited with return code 1
[2023-05-26T01:40:04.789+0000] {taskinstance.py:1824} ERROR - Task failed with exception
Traceback (most recent call last):
  File "/home/airflow/.local/lib/python3.7/site-packages/airflow/operators/bash.py", line 211, in execute
    f"Bash command failed. The command returned a non-zero exit code {result.exit_code}."
airflow.exceptions.AirflowException: Bash command failed. The command returned a non-zero exit code 1.
[2023-05-26T01:40:04.796+0000] {taskinstance.py:1350} INFO - Marking task as FAILED. dag_id=my_dag, task_id=Load, execution_date=20230526T013936, start_date=20230526T014002, end_date=20230526T014004
[2023-05-26T01:40:04.818+0000] {standard_task_runner.py:109} ERROR - Failed to execute job 128 for task Load (Bash command failed. The command returned a non-zero exit code 1.; 600)
[2023-05-26T01:40:04.899+0000] {local_task_job_runner.py:225} INFO - Task exited with return code 1
[2023-05-26T01:40:04.928+0000] {taskinstance.py:2651} INFO - 0 downstream tasks scheduled from follow-on schedule check
